Workbook

Sheet Tareas
A1: ID | B1: ID principal | C1: Tipo | D1: Resumen | E1: Inicio | F1: Fin | G1: Duración (días) | H1: Prioridad | I1: Estado | J1: Etiquetas | K1: Descripción
A2: 1 | C2: Épica | D2: E1 Análisis de universidades y diseño metodológico (OE2) | E2: =DATE(2026,10,13) -> 46308 | F2: =DATE(2026,11,16) -> 46342 | G2: =F2-E2+1 -> 35 | H2: Alta | I2: En curso | J2: OE2 Cap1 Cap2 | K2: Situación de las universidades, referentes nacionales e internacionales y diseño de la metodología (fases P y 0 a 4). Cap. 1 y Cap. 2.
A3: 2 | B3: 1 | C3: Tarea | D3: Revisión de la normativa ecuatoriana (LOPDP; RLOPDP; resoluciones SPDP; LOFC 2026) | E3: =DATE(2026,10,13) -> 46308 | F3: =DATE(2026,10,23) -> 46318 | G3: =F3-E3+1 -> 11 | H3: Alta | I3: Listo | J3: OE2 normativa | K3: Verificar artículos en el texto oficial y registrar en FUENTES.md.
A4: 3 | B4: 1 | C4: Tarea | D4: Estado del arte y brecha (5 ejes; 22 trabajos) | E4: =DATE(2026,10,13) -> 46308 | F4: =DATE(2026,10,30) -> 46325 | G4: =F4-E4+1 -> 18 | H4: Media | I4: Listo | J4: OE2 Cap1 | K4: Tablas de trabajos relacionados y comparativa de marcos (Cap. 1).
A5: 4 | B5: 1 | C5: Tarea | D5: Cifras del sector educativo con fecha de corte | E5: =DATE(2026,10,20) -> 46315 | F5: =DATE(2026,10,30) -> 46325 | G5: =F5-E5+1 -> 11 | H5: Alta | I5: Listo | J5: OE2 Cap1 tutora | K5: MINEDUC; CNII; CES; SPDP. Tabla de cifras y cierre con la brecha (Cap. 1).
A6: 5 | B6: 1 | C6: Tarea | D6: Fundamentación: términos legales; cómo funciona una ley; cronología; comparativa de 6 países; régimen de vulneraciones | E6: =DATE(2026,10,20) -> 46315 | F6: =DATE(2026,10,30) -> 46325 | G6: =F6-E6+1 -> 11 | H6: Alta | I6: Listo | J6: OE2 Cap1 tutora | K6: Indicaciones C13-C16; A1; A5 (Cap. 1).
A7: 6 | B7: 1 | C7: Tarea | D7: Atender observaciones del tribunal y de la tutora (revisión del 27/10/2026) | E7: =DATE(2026,10,27) -> 46322 | F7: =DATE(2026,10,30) -> 46325 | G7: =F7-E7+1 -> 4 | H7: Más alta | I7: En curso | J7: revision-tribunal | K7: CAMBIOS.md con A1-A8; B1-B7; C1-C16. Rama revision-tribunal.
A8: 7 | B8: 1 | C8: Tarea | D8: Diseño de fases P y 0-4 y equivalencia con ISO/IEC 27035 y NIST SP 800-61r3 | E8: =DATE(2026,10,26) -> 46321 | F8: =DATE(2026,11,6) -> 46332 | G8: =F8-E8+1 -> 12 | H8: Alta | I8: Listo | J8: OE2 Cap2 | K8: Figura y tablas de fases (Cap. 2).
A9: 8 | B9: 1 | C9: Tarea | D9: Escalas; tabla de decisión; reglas RA-1 a RA-5; fuentes de estimación | E9: =DATE(2026,11,2) -> 46328 | F9: =DATE(2026,11,13) -> 46339 | G9: =F9-E9+1 -> 12 | H9: Alta | I9: Listo | J9: OE2 Cap2 | K9: Justificación de estimaciones B3 (Cap. 2).
A10: 9 | B10: 1 | C10: Tarea | D10: Verificar la plantilla de matriz (1 057 fórmulas; casos T-01 a T-06) | E10: =DATE(2026,11,9) -> 46335 | F10: =DATE(2026,11,16) -> 46342 | G10: =F10-E10+1 -> 8 | H10: Media | I10: Listo | J10: OE2 matriz | K10: Regenerar con scripts/build_matriz.js y registrar resultados (Cap. 3).
A11: 10 | C11: Épica | D11: E2 Autorización y diagnóstico institucional (OE1) | E11: =DATE(2026,10,27) -> 46322 | F11: =DATE(2026,12,14) -> 46370 | G11: =F11-E11+1 -> 49 | H11: Más alta | I11: Por hacer | J11: OE1 UTI | K11: Requisitos D01-D10 (REQUISITOS_DIAGNOSTICO.md) y diagnóstico del proceso de admisión y matrícula UTI Quito.
A12: 11 | B12: 10 | C12: Tarea | D12: D01 Redactar y entregar la solicitud de autorización formal a la UTI | E12: =DATE(2026,10,27) -> 46322 | F12: =DATE(2026,11,6) -> 46332 | G12: =F12-E12+1 -> 11 | H12: Más alta | I12: Por hacer | J12: OE1 D01 | K12: Con la tutora; incluir condiciones (a)-(e) del Anexo de autorización.
A13: 12 | B13: 10 | C13: Tarea | D13: Hito: oficio de autorización recibido | E13: =DATE(2026,11,20) -> 46346 | F13: =DATE(2026,11,20) -> 46346 | G13: =F13-E13+1 -> 1 | H13: Más alta | I13: Por hacer | J13: OE1 D01 hito | K13: Bloquea D03-D10. Escanear e incorporar al Anexo de autorización.
A14: 13 | B14: 10 | C14: Tarea | D14: Identificar enlace institucional e informantes por subproceso (códigos E01...) | E14: =DATE(2026,11,16) -> 46342 | F14: =DATE(2026,11,20) -> 46346 | G14: =F14-E14+1 -> 5 | H14: Alta | I14: Por hacer | J14: OE1 | K14: Admisiones; Secretaría Académica; Bienestar; Financiero; TI; Jurídico.
A15: 14 | B15: 10 | C15: Tarea | D15: D04-D05 Solicitar datos agregados y documentos vigentes | E15: =DATE(2026,11,23) -> 46349 | F15: =DATE(2026,11,27) -> 46353 | G15: =F15-E15+1 -> 5 | H15: Alta | I15: Por hacer | J15: OE1 D04 D05 | K15: Aspirantes por periodo y % de menores; matriculados; becas; políticas; formularios; contratos con encargados; tabla de conservación.
A16: 15 | B16: 10 | C16: Tarea | D16: D03 Entrevistas semiestructuradas SP1-SP6 (Anexo B) | E16: =DATE(2026,11,23) -> 46349 | F16: =DATE(2026,12,4) -> 46360 | G16: =F16-E16+1 -> 12 | H16: Alta | I16: Por hacer | J16: OE1 D03 | K16: 5-6 entrevistas de 45-60 min con consentimiento (Anexo G).
A17: 16 | B17: 10 | C17: Tarea | D17: D07 Aplicar el cuestionario de madurez (Anexo C) | E17: =DATE(2026,11,30) -> 46356 | F17: =DATE(2026,12,4) -> 46360 | G17: =F17-E17+1 -> 5 | H17: Alta | I17: Por hacer | J17: OE1 D07 | K17: Calcular medianas por dominio y global.
A18: 17 | B18: 10 | C18: Tarea | D18: D06 D08 D09 Auditoría de práctica efectiva; historial de incidentes; DPD | E18: =DATE(2026,11,30) -> 46356 | F18: =DATE(2026,12,9) -> 46365 | G18: =F18-E18+1 -> 10 | H18: Alta | I18: Por hacer | J18: OE1 D06 D08 D09 | K18: Lista de verificación (Anexo A) con evidencia.
A19: 18 | B19: 10 | C19: Tarea | D19: Informe de diagnóstico; RAT y dictamen de gran escala | E19: =DATE(2026,12,7) -> 46363 | F19: =DATE(2026,12,14) -> 46370 | G19: =F19-E19+1 -> 8 | H19: Alta | I19: Por hacer | J19: OE1 Cap3 | K19: Completar Tablas de madurez; verificación normativa y RAT (Cap. 3).
A20: 19 | C20: Épica | D20: E3 Implementación de la metodología en la UTI (OE3) | E20: =DATE(2026,11,24) -> 46350 | F20: =DATE(2027,1,18) -> 46405 | G20: =F20-E20+1 -> 56 | H20: Alta | I20: Por hacer | J20: OE3 | K20: Escenarios; Delphi; matriz inherente y residual; plan de tratamiento y trazabilidad.
A21: 20 | B21: 19 | C21: Tarea | D21: D10 Convocar al panel (7-8 candidatos) y aplicar la autoevaluación de competencia K | E21: =DATE(2026,11,24) -> 46350 | F21: =DATE(2026,12,4) -> 46360 | G21: =F21-E21+1 -> 11 | H21: Alta | I21: Por hacer | J21: OE3 OE4 D10 | K21: Anexo de competencia; consentimiento (Anexo G).
A22: 21 | B22: 19 | C22: Tarea | D22: Calibración del panel con el puntaje de Brier (Anexo E) | E22: =DATE(2026,12,7) -> 46363 | F22: =DATE(2026,12,11) -> 46367 | G22: =F22-E22+1 -> 5 | H22: Alta | I22: Por hacer | J22: OE3 Delphi | K22: Registrar en la hoja Brier; pesos por experto.
A23: 22 | B23: 19 | C23: Tarea | D23: Fase 1: confirmar; reformular o descartar escenarios R-01 a R-13 | E23: =DATE(2026,12,10) -> 46366 | F23: =DATE(2026,12,16) -> 46372 | G23: =F23-E23+1 -> 7 | H23: Alta | I23: Por hacer | J23: OE3 | K23: Según el diagnóstico; añadir escenarios no previstos.
A24: 23 | B24: 19 | C24: Tarea | D24: Delphi ronda 1 (Anexo D) | E24: =DATE(2026,12,14) -> 46370 | F24: =DATE(2026,12,18) -> 46374 | G24: =F24-E24+1 -> 5 | H24: Alta | I24: Por hacer | J24: OE3 Delphi | K24: Probabilidad anual e impacto con rationale.
A25: 24 | B25: 19 | C25: Tarea | D25: Delphi ronda 2 | E25: =DATE(2027,1,4) -> 46391 | F25: =DATE(2027,1,8) -> 46395 | G25: =F25-E25+1 -> 5 | H25: Alta | I25: Por hacer | J25: OE3 Delphi | K25: Retroalimentación de mediana; RIC y argumentos. Receso 21/12/2026-01/01/2027.
A26: 25 | B26: 19 | C26: Tarea | D26: Delphi ronda 3 (solo escenarios sin consenso) | E26: =DATE(2027,1,11) -> 46398 | F26: =DATE(2027,1,13) -> 46400 | G26: =F26-E26+1 -> 3 | H26: Media | I26: Por hacer | J26: OE3 Delphi | K26: Consenso: RIC <= 1 y >= 70 % a ±1 nivel; W de Kendall.
A27: 26 | B27: 19 | C27: Tarea | D27: Matriz de riesgo inherente y evaluación de impacto (Fase 2) | E27: =DATE(2027,1,11) -> 46398 | F27: =DATE(2027,1,15) -> 46402 | G27: =F27-E27+1 -> 5 | H27: Alta | I27: Por hacer | J27: OE3 Cap3 | K27: Completar Tablas de riesgo inherente y de EIPD (Cap. 3).
A28: 27 | B28: 19 | C28: Tarea | D28: Plan de tratamiento; riesgo residual y confirmación de la trazabilidad (Fase 3) | E28: =DATE(2027,1,13) -> 46400 | F28: =DATE(2027,1,18) -> 46405 | G28: =F28-E28+1 -> 6 | H28: Alta | I28: Por hacer | J28: OE3 Cap3 | K28: Opción; residual; reglas RA; roles y plazos confirmados por la UTI.
A29: 28 | C29: Épica | D29: E4 Evaluación de la metodología (OE4) | E29: =DATE(2027,1,5) -> 46392 | F29: =DATE(2027,2,8) -> 46426 | G29: =F29-E29+1 -> 35 | H29: Alta | I29: Por hacer | J29: OE4 | K29: Escenarios de validación V1 y V2; juicio de expertos; indicadores IV01-IV12; recomendaciones.
A30: 29 | B30: 28 | C30: Tarea | D30: Preparar el simulacro de vulneración V2 (Anexo del simulacro) | E30: =DATE(2027,1,5) -> 46392 | F30: =DATE(2027,1,15) -> 46402 | G30: =F30-E30+1 -> 11 | H30: Media | I30: Por hacer | J30: OE4 V2 | K30: Inyecciones T0-T5; participantes; lista de art. 26 RLOPDP.
A31: 30 | B31: 28 | C31: Tarea | D31: Ejecutar el simulacro V2 y registrar tiempos | E31: =DATE(2027,1,19) -> 46406 | F31: =DATE(2027,1,22) -> 46409 | G31: =F31-E31+1 -> 4 | H31: Alta | I31: Por hacer | J31: OE4 V2 | K31: IV10 (<= 72 h internas; término de 5 días) e IV11 (8/8 elementos).
A32: 31 | B32: 28 | C32: Tarea | D32: Juicio de expertos sobre la metodología (Anexo F) | E32: =DATE(2027,1,19) -> 46406 | F32: =DATE(2027,1,29) -> 46416 | G32: =F32-E32+1 -> 11 | H32: Alta | I32: Por hacer | J32: OE4 | K32: Calificaciones V01-V12 y observaciones.
A33: 32 | B33: 28 | C33: Tarea | D33: Calcular indicadores IV04-IV12; V de Aiken y W de Kendall | E33: =DATE(2027,1,26) -> 46413 | F33: =DATE(2027,2,5) -> 46423 | G33: =F33-E33+1 -> 11 | H33: Alta | I33: Por hacer | J33: OE4 Cap3 | K33: Completar Tablas de indicadores; panel; Delphi y juicio de expertos (Cap. 3).
A34: 33 | B34: 28 | C34: Tarea | D34: Formular recomendaciones de mejora continua | E34: =DATE(2027,2,1) -> 46419 | F34: =DATE(2027,2,5) -> 46423 | G34: =F34-E34+1 -> 5 | H34: Media | I34: Por hacer | J34: OE4 Cap4 | K34: Derivadas de resultados (Cap. 4).
A35: 34 | C35: Épica | D35: E5 Documentación final y sustentación | E35: =DATE(2027,1,25) -> 46412 | F35: =DATE(2027,2,26) -> 46444 | G35: =F35-E35+1 -> 33 | H35: Alta | I35: Por hacer | J35: documentacion | K35: Cierre del documento; aprobaciones y defensa.
A36: 35 | B36: 34 | C36: Tarea | D36: Actualizar Cap. 3 y Cap. 4 con los resultados reales | E36: =DATE(2027,1,25) -> 46412 | F36: =DATE(2027,2,5) -> 46423 | G36: =F36-E36+1 -> 12 | H36: Alta | I36: Por hacer | J36: Cap3 Cap4 | K36: Una conclusión por OE con resultados verificables.
A37: 36 | B37: 34 | C37: Tarea | D37: Resumen; abstract y revisión formal final (IEEE; guiones; referencias) | E37: =DATE(2027,2,10) -> 46428 | F37: =DATE(2027,2,12) -> 46430 | G37: =F37-E37+1 -> 3 | H37: Media | I37: Por hacer | J37: formal | K37: Compilar sin errores ni referencias indefinidas.
A38: 37 | B38: 34 | C38: Tarea | D38: Revisión y aprobación de la tutora | E38: =DATE(2027,2,10) -> 46428 | F38: =DATE(2027,2,16) -> 46434 | G38: =F38-E38+1 -> 7 | H38: Más alta | I38: Por hacer | J38: tutora | K38: Firma de la aprobación de la tutora (Preliminares).
A39: 38 | B39: 34 | C39: Tarea | D39: Revisión y aprobación de los lectores | E39: =DATE(2027,2,16) -> 46434 | F39: =DATE(2027,2,22) -> 46440 | G39: =F39-E39+1 -> 7 | H39: Más alta | I39: Por hacer | J39: lectores | K39: Andrés Rubio Proaño PhD. y Jaime Fabrizzio Peñafiel MSc.
A40: 39 | B40: 34 | C40: Tarea | D40: Preparar la sustentación (presentación y ensayo) | E40: =DATE(2027,2,16) -> 46434 | F40: =DATE(2027,2,25) -> 46443 | G40: =F40-E40+1 -> 10 | H40: Alta | I40: Por hacer | J40: sustentacion | K40: Diapositivas; demostración de la plantilla; preguntas previstas.
...

Sheet Gantt
A1: Planificación del proyecto ITI-TFG-B26-0021 — 13 de octubre de 2026 a 26 de febrero de 2027
A2: Leyenda: azul oscuro = épica · azul = tarea · verde = tarea lista · naranja = hito · «Hoy» en rojo = semana actual. Las barras se calculan con las fechas de la hoja Tareas.
F3: =IF(AND(TODAY()>=F$4,TODAY()<F$4+7),"Hoy","S1") -> S1 | G3: =IF(AND(TODAY()>=G$4,TODAY()<G$4+7),"Hoy","S2") -> S2 | H3: =IF(AND(TODAY()>=H$4,TODAY()<H$4+7),"Hoy","S3") -> Hoy | I3: =IF(AND(TODAY()>=I$4,TODAY()<I$4+7),"Hoy","S4") -> S4 | J3: =IF(AND(TODAY()>=J$4,TODAY()<J$4+7),"Hoy","S5") -> S5 | K3: =IF(AND(TODAY()>=K$4,TODAY()<K$4+7),"Hoy","S6") -> S6 | L3: =IF(AND(TODAY()>=L$4,TODAY()<L$4+7),"Hoy","S7") -> S7 | M3: =IF(AND(TODAY()>=M$4,TODAY()<M$4+7),"Hoy","S8") -> S8 | N3: =IF(AND(TODAY()>=N$4,TODAY()<N$4+7),"Hoy","S9") -> S9 | O3: =IF(AND(TODAY()>=O$4,TODAY()<O$4+7),"Hoy","S10") -> S10 | P3: =IF(AND(TODAY()>=P$4,TODAY()<P$4+7),"Hoy","S11") -> S11 | Q3: =IF(AND(TODAY()>=Q$4,TODAY()<Q$4+7),"Hoy","S12") -> S12 | R3: =IF(AND(TODAY()>=R$4,TODAY()<R$4+7),"Hoy","S13") -> S13 | S3: =IF(AND(TODAY()>=S$4,TODAY()<S$4+7),"Hoy","S14") -> S14 | T3: =IF(AND(TODAY()>=T$4,TODAY()<T$4+7),"Hoy","S15") -> S15 | U3: =IF(AND(TODAY()>=U$4,TODAY()<U$4+7),"Hoy","S16") -> S16 | V3: =IF(AND(TODAY()>=V$4,TODAY()<V$4+7),"Hoy","S17") -> S17 | W3: =IF(AND(TODAY()>=W$4,TODAY()<W$4+7),"Hoy","S18") -> S18 | X3: =IF(AND(TODAY()>=X$4,TODAY()<X$4+7),"Hoy","S19") -> S19 | Y3: =IF(AND(TODAY()>=Y$4,TODAY()<Y$4+7),"Hoy","S20") -> S20
A4: ID | B4: Actividad | C4: Inicio | D4: Fin | E4: Estado | F4: =DATE(2026,10,13) -> 46308 | G4: =DATE(2026,10,20) -> 46315 | H4: =DATE(2026,10,27) -> 46322 | I4: =DATE(2026,11,3) -> 46329 | J4: =DATE(2026,11,10) -> 46336 | K4: =DATE(2026,11,17) -> 46343 | L4: =DATE(2026,11,24) -> 46350 | M4: =DATE(2026,12,1) -> 46357 | N4: =DATE(2026,12,8) -> 46364 | O4: =DATE(2026,12,15) -> 46371 | P4: =DATE(2026,12,22) -> 46378 | Q4: =DATE(2026,12,29) -> 46385 | R4: =DATE(2027,1,5) -> 46392 | S4: =DATE(2027,1,12) -> 46399 | T4: =DATE(2027,1,19) -> 46406 | U4: =DATE(2027,1,26) -> 46413 | V4: =DATE(2027,2,2) -> 46420 | W4: =DATE(2027,2,9) -> 46427 | X4: =DATE(2027,2,16) -> 46434 | Y4: =DATE(2027,2,23) -> 46441
A5: =Tareas!A2 -> 1 | B5: =IF(Tareas!C2="Épica",Tareas!D2," "&Tareas!D2) -> E1 Análisis de universidades y diseño metodológico (OE2) | C5: =Tareas!E2 -> 46308 | D5: =Tareas!F2 -> 46342 | E5: =Tareas!I2 -> En curso | F5: =IF(AND($C5<=F$4+6,$D5>=F$4),$Z5,"") -> E | G5: =IF(AND($C5<=G$4+6,$D5>=G$4),$Z5,"") -> E | H5: =IF(AND($C5<=H$4+6,$D5>=H$4),$Z5,"") -> E | I5: =IF(AND($C5<=I$4+6,$D5>=I$4),$Z5,"") -> E | J5: =IF(AND($C5<=J$4+6,$D5>=J$4),$Z5,"") -> E | K5: =IF(AND($C5<=K$4+6,$D5>=K$4),$Z5,"") | L5: =IF(AND($C5<=L$4+6,$D5>=L$4),$Z5,"") | M5: =IF(AND($C5<=M$4+6,$D5>=M$4),$Z5,"") | ... Y5: =IF(AND($C5<=Y$4+6,$D5>=Y$4),$Z5,"") | Z5: =IF(ISNUMBER(SEARCH("hito",Tareas!J2)),"H",IF(Tareas!C2="Épica","E",IF(Tareas!I2="Listo","L","T"))) -> E
A6: =Tareas!A3 -> 2 | B6: =IF(Tareas!C3="Épica",Tareas!D3," "&Tareas!D3) -> Revisión de la normativa ecuatoriana (LOPDP; RLOPDP; resoluciones SPDP; LOFC 2026) | C6: =Tareas!E3 -> 46308 | D6: =Tareas!F3 -> 46318 | E6: =Tareas!I3 -> Listo | F6: =IF(AND($C6<=F$4+6,$D6>=F$4),$Z6,"") -> L | G6: =IF(AND($C6<=G$4+6,$D6>=G$4),$Z6,"") -> L | H6: =IF(AND($C6<=H$4+6,$D6>=H$4),$Z6,"") | I6: =IF(AND($C6<=I$4+6,$D6>=I$4),$Z6,"") | J6: =IF(AND($C6<=J$4+6,$D6>=J$4),$Z6,"") | K6: =IF(AND($C6<=K$4+6,$D6>=K$4),$Z6,"") | L6: =IF(AND($C6<=L$4+6,$D6>=L$4),$Z6,"") | M6: =IF(AND($C6<=M$4+6,$D6>=M$4),$Z6,"") | ... Y6: =IF(AND($C6<=Y$4+6,$D6>=Y$4),$Z6,"") | Z6: =IF(ISNUMBER(SEARCH("hito",Tareas!J3)),"H",IF(Tareas!C3="Épica","E",IF(Tareas!I3="Listo","L","T"))) -> L
A7: =Tareas!A4 -> 3 | B7: =IF(Tareas!C4="Épica",Tareas!D4," "&Tareas!D4) -> Estado del arte y brecha (5 ejes; 22 trabajos) | C7: =Tareas!E4 -> 46308 | D7: =Tareas!F4 -> 46325 | E7: =Tareas!I4 -> Listo | F7: =IF(AND($C7<=F$4+6,$D7>=F$4),$Z7,"") -> L | G7: =IF(AND($C7<=G$4+6,$D7>=G$4),$Z7,"") -> L | H7: =IF(AND($C7<=H$4+6,$D7>=H$4),$Z7,"") -> L | I7: =IF(AND($C7<=I$4+6,$D7>=I$4),$Z7,"") | J7: =IF(AND($C7<=J$4+6,$D7>=J$4),$Z7,"") | K7: =IF(AND($C7<=K$4+6,$D7>=K$4),$Z7,"") | L7: =IF(AND($C7<=L$4+6,$D7>=L$4),$Z7,"") | M7: =IF(AND($C7<=M$4+6,$D7>=M$4),$Z7,"") | ... Y7: =IF(AND($C7<=Y$4+6,$D7>=Y$4),$Z7,"") | Z7: =IF(ISNUMBER(SEARCH("hito",Tareas!J4)),"H",IF(Tareas!C4="Épica","E",IF(Tareas!I4="Listo","L","T"))) -> L
A8: =Tareas!A5 -> 4 | B8: =IF(Tareas!C5="Épica",Tareas!D5," "&Tareas!D5) -> Cifras del sector educativo con fecha de corte | C8: =Tareas!E5 -> 46315 | D8: =Tareas!F5 -> 46325 | E8: =Tareas!I5 -> Listo | F8: =IF(AND($C8<=F$4+6,$D8>=F$4),$Z8,"") | G8: =IF(AND($C8<=G$4+6,$D8>=G$4),$Z8,"") -> L | H8: =IF(AND($C8<=H$4+6,$D8>=H$4),$Z8,"") -> L | I8: =IF(AND($C8<=I$4+6,$D8>=I$4),$Z8,"") | J8: =IF(AND($C8<=J$4+6,$D8>=J$4),$Z8,"") | K8: =IF(AND($C8<=K$4+6,$D8>=K$4),$Z8,"") | L8: =IF(AND($C8<=L$4+6,$D8>=L$4),$Z8,"") | M8: =IF(AND($C8<=M$4+6,$D8>=M$4),$Z8,"") | ... Y8: =IF(AND($C8<=Y$4+6,$D8>=Y$4),$Z8,"") | Z8: =IF(ISNUMBER(SEARCH("hito",Tareas!J5)),"H",IF(Tareas!C5="Épica","E",IF(Tareas!I5="Listo","L","T"))) -> L
A9: =Tareas!A6 -> 5 | B9: =IF(Tareas!C6="Épica",Tareas!D6," "&Tareas!D6) -> Fundamentación: términos legales; cómo funciona una ley; cronología; comparativa de 6 países; régimen de vulneraciones | C9: =Tareas!E6 -> 46315 | D9: =Tareas!F6 -> 46325 | E9: =Tareas!I6 -> Listo | F9: =IF(AND($C9<=F$4+6,$D9>=F$4),$Z9,"") | G9: =IF(AND($C9<=G$4+6,$D9>=G$4),$Z9,"") -> L | H9: =IF(AND($C9<=H$4+6,$D9>=H$4),$Z9,"") -> L | I9: =IF(AND($C9<=I$4+6,$D9>=I$4),$Z9,"") | J9: =IF(AND($C9<=J$4+6,$D9>=J$4),$Z9,"") | K9: =IF(AND($C9<=K$4+6,$D9>=K$4),$Z9,"") | L9: =IF(AND($C9<=L$4+6,$D9>=L$4),$Z9,"") | M9: =IF(AND($C9<=M$4+6,$D9>=M$4),$Z9,"") | ... Y9: =IF(AND($C9<=Y$4+6,$D9>=Y$4),$Z9,"") | Z9: =IF(ISNUMBER(SEARCH("hito",Tareas!J6)),"H",IF(Tareas!C6="Épica","E",IF(Tareas!I6="Listo","L","T"))) -> L
A10: =Tareas!A7 -> 6 | B10: =IF(Tareas!C7="Épica",Tareas!D7," "&Tareas!D7) -> Atender observaciones del tribunal y de la tutora (revisión del 27/10/2026) | C10: =Tareas!E7 -> 46322 | D10: =Tareas!F7 -> 46325 | E10: =Tareas!I7 -> En curso | F10: =IF(AND($C10<=F$4+6,$D10>=F$4),$Z10,"") | G10: =IF(AND($C10<=G$4+6,$D10>=G$4),$Z10,"") | H10: =IF(AND($C10<=H$4+6,$D10>=H$4),$Z10,"") -> T | I10: =IF(AND($C10<=I$4+6,$D10>=I$4),$Z10,"") | J10: =IF(AND($C10<=J$4+6,$D10>=J$4),$Z10,"") | K10: =IF(AND($C10<=K$4+6,$D10>=K$4),$Z10,"") | L10: =IF(AND($C10<=L$4+6,$D10>=L$4),$Z10,"") | M10: =IF(AND($C10<=M$4+6,$D10>=M$4),$Z10,"") | ... Y10: =IF(AND($C10<=Y$4+6,$D10>=Y$4),$Z10,"") | Z10: =IF(ISNUMBER(SEARCH("hito",Tareas!J7)),"H",IF(Tareas!C7="Épica","E",IF(Tareas!I7="Listo","L","T"))) -> T
A11: =Tareas!A8 -> 7 | B11: =IF(Tareas!C8="Épica",Tareas!D8," "&Tareas!D8) -> Diseño de fases P y 0-4 y equivalencia con ISO/IEC 27035 y NIST SP 800-61r3 | C11: =Tareas!E8 -> 46321 | D11: =Tareas!F8 -> 46332 | E11: =Tareas!I8 -> Listo | F11: =IF(AND($C11<=F$4+6,$D11>=F$4),$Z11,"") | G11: =IF(AND($C11<=G$4+6,$D11>=G$4),$Z11,"") -> L | H11: =IF(AND($C11<=H$4+6,$D11>=H$4),$Z11,"") -> L | I11: =IF(AND($C11<=I$4+6,$D11>=I$4),$Z11,"") -> L | J11: =IF(AND($C11<=J$4+6,$D11>=J$4),$Z11,"") | K11: =IF(AND($C11<=K$4+6,$D11>=K$4),$Z11,"") | L11: =IF(AND($C11<=L$4+6,$D11>=L$4),$Z11,"") | M11: =IF(AND($C11<=M$4+6,$D11>=M$4),$Z11,"") | ... Y11: =IF(AND($C11<=Y$4+6,$D11>=Y$4),$Z11,"") | Z11: =IF(ISNUMBER(SEARCH("hito",Tareas!J8)),"H",IF(Tareas!C8="Épica","E",IF(Tareas!I8="Listo","L","T"))) -> L
A12: =Tareas!A9 -> 8 | B12: =IF(Tareas!C9="Épica",Tareas!D9," "&Tareas!D9) -> Escalas; tabla de decisión; reglas RA-1 a RA-5; fuentes de estimación | C12: =Tareas!E9 -> 46328 | D12: =Tareas!F9 -> 46339 | E12: =Tareas!I9 -> Listo | F12: =IF(AND($C12<=F$4+6,$D12>=F$4),$Z12,"") | G12: =IF(AND($C12<=G$4+6,$D12>=G$4),$Z12,"") | H12: =IF(AND($C12<=H$4+6,$D12>=H$4),$Z12,"") -> L | I12: =IF(AND($C12<=I$4+6,$D12>=I$4),$Z12,"") -> L | J12: =IF(AND($C12<=J$4+6,$D12>=J$4),$Z12,"") -> L | K12: =IF(AND($C12<=K$4+6,$D12>=K$4),$Z12,"") | L12: =IF(AND($C12<=L$4+6,$D12>=L$4),$Z12,"") | M12: =IF(AND($C12<=M$4+6,$D12>=M$4),$Z12,"") | ... Y12: =IF(AND($C12<=Y$4+6,$D12>=Y$4),$Z12,"") | Z12: =IF(ISNUMBER(SEARCH("hito",Tareas!J9)),"H",IF(Tareas!C9="Épica","E",IF(Tareas!I9="Listo","L","T"))) -> L
A13: =Tareas!A10 -> 9 | B13: =IF(Tareas!C10="Épica",Tareas!D10," "&Tareas!D10) -> Verificar la plantilla de matriz (1 057 fórmulas; casos T-01 a T-06) | C13: =Tareas!E10 -> 46335 | D13: =Tareas!F10 -> 46342 | E13: =Tareas!I10 -> Listo | F13: =IF(AND($C13<=F$4+6,$D13>=F$4),$Z13,"") | G13: =IF(AND($C13<=G$4+6,$D13>=G$4),$Z13,"") | H13: =IF(AND($C13<=H$4+6,$D13>=H$4),$Z13,"") | I13: =IF(AND($C13<=I$4+6,$D13>=I$4),$Z13,"") -> L | J13: =IF(AND($C13<=J$4+6,$D13>=J$4),$Z13,"") -> L | K13: =IF(AND($C13<=K$4+6,$D13>=K$4),$Z13,"") | L13: =IF(AND($C13<=L$4+6,$D13>=L$4),$Z13,"") | M13: =IF(AND($C13<=M$4+6,$D13>=M$4),$Z13,"") | ... Y13: =IF(AND($C13<=Y$4+6,$D13>=Y$4),$Z13,"") | Z13: =IF(ISNUMBER(SEARCH("hito",Tareas!J10)),"H",IF(Tareas!C10="Épica","E",IF(Tareas!I10="Listo","L","T"))) -> L
A14: =Tareas!A11 -> 10 | B14: =IF(Tareas!C11="Épica",Tareas!D11," "&Tareas!D11) -> E2 Autorización y diagnóstico institucional (OE1) | C14: =Tareas!E11 -> 46322 | D14: =Tareas!F11 -> 46370 | E14: =Tareas!I11 -> Por hacer | F14: =IF(AND($C14<=F$4+6,$D14>=F$4),$Z14,"") | G14: =IF(AND($C14<=G$4+6,$D14>=G$4),$Z14,"") | H14: =IF(AND($C14<=H$4+6,$D14>=H$4),$Z14,"") -> E | I14: =IF(AND($C14<=I$4+6,$D14>=I$4),$Z14,"") -> E | J14: =IF(AND($C14<=J$4+6,$D14>=J$4),$Z14,"") -> E | K14: =IF(AND($C14<=K$4+6,$D14>=K$4),$Z14,"") -> E | L14: =IF(AND($C14<=L$4+6,$D14>=L$4),$Z14,"") -> E | M14: =IF(AND($C14<=M$4+6,$D14>=M$4),$Z14,"") -> E | ... Y14: =IF(AND($C14<=Y$4+6,$D14>=Y$4),$Z14,"") | Z14: =IF(ISNUMBER(SEARCH("hito",Tareas!J11)),"H",IF(Tareas!C11="Épica","E",IF(Tareas!I11="Listo","L","T"))) -> E
A15: =Tareas!A12 -> 11 | B15: =IF(Tareas!C12="Épica",Tareas!D12," "&Tareas!D12) -> D01 Redactar y entregar la solicitud de autorización formal a la UTI | C15: =Tareas!E12 -> 46322 | D15: =Tareas!F12 -> 46332 | E15: =Tareas!I12 -> Por hacer | F15: =IF(AND($C15<=F$4+6,$D15>=F$4),$Z15,"") | G15: =IF(AND($C15<=G$4+6,$D15>=G$4),$Z15,"") | H15: =IF(AND($C15<=H$4+6,$D15>=H$4),$Z15,"") -> T | I15: =IF(AND($C15<=I$4+6,$D15>=I$4),$Z15,"") -> T | J15: =IF(AND($C15<=J$4+6,$D15>=J$4),$Z15,"") | K15: =IF(AND($C15<=K$4+6,$D15>=K$4),$Z15,"") | L15: =IF(AND($C15<=L$4+6,$D15>=L$4),$Z15,"") | M15: =IF(AND($C15<=M$4+6,$D15>=M$4),$Z15,"") | ... Y15: =IF(AND($C15<=Y$4+6,$D15>=Y$4),$Z15,"") | Z15: =IF(ISNUMBER(SEARCH("hito",Tareas!J12)),"H",IF(Tareas!C12="Épica","E",IF(Tareas!I12="Listo","L","T"))) -> T
A16: =Tareas!A13 -> 12 | B16: =IF(Tareas!C13="Épica",Tareas!D13," "&Tareas!D13) -> Hito: oficio de autorización recibido | C16: =Tareas!E13 -> 46346 | D16: =Tareas!F13 -> 46346 | E16: =Tareas!I13 -> Por hacer | F16: =IF(AND($C16<=F$4+6,$D16>=F$4),$Z16,"") | G16: =IF(AND($C16<=G$4+6,$D16>=G$4),$Z16,"") | H16: =IF(AND($C16<=H$4+6,$D16>=H$4),$Z16,"") | I16: =IF(AND($C16<=I$4+6,$D16>=I$4),$Z16,"") | J16: =IF(AND($C16<=J$4+6,$D16>=J$4),$Z16,"") | K16: =IF(AND($C16<=K$4+6,$D16>=K$4),$Z16,"") -> H | L16: =IF(AND($C16<=L$4+6,$D16>=L$4),$Z16,"") | M16: =IF(AND($C16<=M$4+6,$D16>=M$4),$Z16,"") | ... Y16: =IF(AND($C16<=Y$4+6,$D16>=Y$4),$Z16,"") | Z16: =IF(ISNUMBER(SEARCH("hito",Tareas!J13)),"H",IF(Tareas!C13="Épica","E",IF(Tareas!I13="Listo","L","T"))) -> H
... A44: =Tareas!A41 -> 40 | B44: =IF(Tareas!C41="Épica",Tareas!D41," "&Tareas!D41) -> Hito: entrega final del trabajo de integración curricular | C44: =Tareas!E41 -> 46444 | D44: =Tareas!F41 -> 46444 | E44: =Tareas!I41 -> Por hacer | F44: =IF(AND($C44<=F$4+6,$D44>=F$4),$Z44,"") | G44: =IF(AND($C44<=G$4+6,$D44>=G$4),$Z44,"") | H44: =IF(AND($C44<=H$4+6,$D44>=H$4),$Z44,"") | I44: =IF(AND($C44<=I$4+6,$D44>=I$4),$Z44,"") | J44: =IF(AND($C44<=J$4+6,$D44>=J$4),$Z44,"") | K44: =IF(AND($C44<=K$4+6,$D44>=K$4),$Z44,"") | L44: =IF(AND($C44<=L$4+6,$D44>=L$4),$Z44,"") | M44: =IF(AND($C44<=M$4+6,$D44>=M$4),$Z44,"") | ... Y44: =IF(AND($C44<=Y$4+6,$D44>=Y$4),$Z44,"") -> H | Z44: =IF(ISNUMBER(SEARCH("hito",Tareas!J41)),"H",IF(Tareas!C41="Épica","E",IF(Tareas!I41="Listo","L","T"))) -> H
