Workbook

Sheet Instrucciones
A1: Plantilla de matriz de riesgos del tratamiento de datos personales (LOPDP)
A2: Trabajo de integración curricular — Ramón Alejandro Manzaba Castro — UTI, 2026
A4: Propósito | B4: Registrar, evaluar y monitorear los escenarios de riesgo del tratamiento de datos personales conforme a la metodología del Capítulo 2 (fases 0 a 4), la LOPDP, su Reglamento General y la guía de gestión de riesgos de la SPDP (V.2, 2026).
A5: Leyenda | B5: Celdas amarillas: datos que ingresa el usuario. Celdas grises: fórmulas (no editar). Las listas desplegables provienen de la hoja Listas.
A6: Paso 1 | B6: Fase 1 (identificación): completar en Matriz los bloques "Identificación del tratamiento" y "Escenario de riesgo". Una fila por escenario y por dimensión (confidencialidad, integridad, disponibilidad o licitud). Usar los catálogos de Amenazas y Controles como punto de partida.
A7: Paso 2 | B7: Fase 2 (evaluación): calibrar a los expertos en la hoja Brier, registrar las rondas en Delphi y trasladar a Matriz la probabilidad anual y el impacto sobre el titular con su rationale. Indicar el número de agravantes (hoja Escalas). El impacto ajustado y el nivel inherente se calculan solos.
A8: Paso 3 | B8: Fase 3 (mitigación): elegir el tratamiento, proponer controles (ref. ISO/IEC 27002:2022), responsable y plazo, y estimar la probabilidad y el impacto residuales. El nivel residual, la necesidad de EIPD y el criterio de aceptación se calculan solos.
A9: Paso 4 | B9: Fase 4 (monitoreo): definir el indicador, actualizar el estado y revisar la matriz periódicamente o ante incidentes. La hoja Mapa de calor resume los resultados.
A10: Reglas de la guía SPDP | B10: Toda estimación lleva su rationale; la probabilidad se refiere a un año; C, I, D y licitud se modelan por separado; el nivel se asigna por tabla (hoja Decisión), no multiplicando etiquetas; un impacto muy alto sobre el titular nunca queda por debajo de nivel alto.
A11: Confidencialidad | B11: No registrar datos personales reales. Describir procesos, sistemas y categorías de datos; usar códigos para personas (E01, E02…).
A12: Caso aplicado | B12: Este archivo contiene la matriz aplicada al caso simulado IES-S (Capítulo 3). Las hojas Delphi y Brier están vacías hasta que el panel de expertos participe; las estimaciones de la hoja Matriz son preliminares.

Sheet Matriz
A1: Matriz de riesgos del tratamiento de datos personales — LOPDP
A2: Matriz aplicada al caso simulado IES-S (proceso de admisión y matrícula). Probabilidades e impactos: estimaciones preliminares del investigador, pendientes de calibración con el panel Delphi.
A3: Identificación del tratamiento | I3: Escenario de riesgo | P3: Riesgo inherente | X3: Tratamiento | AB3: Riesgo residual | AG3: Monitoreo
A4: ID | B4: Proceso / subproceso | C4: Actividad de tratamiento | D4: Categorías de datos | E4: ¿Categoría especial? | F4: Titulares (tipo y n.º estimado) | G4: ¿Grupo vulnerable? | H4: Activo / sistema | I4: Dimensión (C/I/D/Licitud) | J4: Comunidad de amenaza | K4: Vector | L4: Vulnerabilidad | M4: Tipo de vulnerabilidad | N4: Art. LOPDP / norma SPDP | O4: Control existente | P4: Probabilidad inherente (lapso anual) | Q4: Rationale probabilidad | R4: Impacto inherente (titular) | S4: Impacto (responsable) | T4: Rationale impacto | U4: Agravantes (n.º) | V4: Impacto ajustado (titular) | W4: Nivel inherente | X4: Tratamiento | Y4: Control propuesto (ref. ISO/IEC 27002) | Z4: Responsable | AA4: Plazo | AB4: Probabilidad residual | AC4: Impacto residual (ajustado) | AD4: Nivel residual | AE4: ¿Requiere EIPD? | AF4: Aceptación del riesgo residual | AG4: Indicador de monitoreo | AH4: Estado
A5: R-01 | B5: SP3. Becas y aranceles diferenciados | C5: Recepción y almacenamiento de certificados de discapacidad y fichas socioeconómicas | D5: Discapacidad y salud; socioeconómicos; identificación | E5: Sí | F5: Postulantes a beca y su núcleo familiar (≈1 200) | G5: Sí | H5: Carpetas compartidas en la nube (Bienestar Estudiantil) | I5: Confidencialidad | J5: Personal interno (error humano); ciberdelincuencia | K5: Enlace de carpeta compartido como público o acceso con credenciales robadas | L5: Documentos recibidos por correo y guardados sin clasificación ni restricción de acceso | M5: Organizacional | N5: LOPDP arts. 25, 37 y 40 | O5: Contraseña institucional sin MFA | P5: Media | Q5: Estimación preliminar del investigador: la exposición por enlaces compartidos y el error humano son causas frecuentes de incidentes en universidades (Ulven y Wangen, 2021; Álvarez-Carrión y Hernández-Sotomayor, 2024); sin controles de fuga se espera aproximadamente un evento cada 1 a 2 años. | R5: Alto | S5: Alto | T5: Exposición de discapacidad y condición socioeconómica: riesgo de discriminación y exclusión de beneficios. Agravante: categorías especiales y grupo vulnerable (art. 25). | U5: 1 | V5: =IF(R5="","",INDEX(Listas!$B$2:$B$6,MIN(5,MATCH(R5,Listas!$B$2:$B$6,0)+IF(U5="",0,U5)))) -> Muy alto | W5: =IF(OR(P5="",V5=""),"",INDEX('Decisión'!$B$4:$F$8,MATCH(P5,'Decisión'!$A$4:$A$8,0),MATCH(V5,'Decisión'!$B$3:$F$3,0))) -> Muy alto | X5: Mitigar | Y5: 5.12 Clasificación; 5.15 Control de acceso; 8.5 Autenticación multifactor; 8.12 Prevención de fuga; minimización (registrar solo la verificación del certificado) | Z5: Dirección de TI y Bienestar Estudiantil | AA5: 3 meses | AB5: Baja | AC5: Medio | AD5: =IF(OR(AB5="",AC5=""),"",INDEX('Decisión'!$B$4:$F$8,MATCH(AB5,'Decisión'!$A$4:$A$8,0),MATCH(AC5,'Decisión'!$B$3:$F$3,0))) -> Medio | AE5: =IF(W5="","",IF(OR(W5="Alto",W5="Muy alto"),IF(OR(E5="Sí",G5="Sí"),"Sí (obligatoria)","Valorar"),"Recomendada por defecto")) -> Sí (obligatoria) | AF5: =IF(AD5="","",IF(AC5="Muy alto","Requiere observaciones DPD/jurídico y aprobación de la máxima autoridad",IF(OR(AD5="Muy bajo",AD5="Bajo"),"Aceptable (registrar y monitorear)",IF(AD5="Medio","Tratar en plan anual o aceptación formal","No aceptable: tratamiento prioritario")))) -> Tratar en plan anual o aceptación formal | AG5: N.º de enlaces públicos detectados por mes en carpetas restringidas (meta: 0) | AH5: En tratamiento
A6: R-02 | B6: SP1. Registro y postulación | C6: Gestión de postulaciones en el CRM de admisiones | D6: Identificación; contacto; fecha de nacimiento; colegio de procedencia | E6: No | F6: Aspirantes (≈5 000 por año), ≈10 % menores de edad | G6: Sí | H6: CRM de admisiones (SaaS, encargado) | I6: Confidencialidad | J6: Ciberdelincuencia organizada | K6: Phishing dirigido al personal de admisiones | L6: Autenticación solo con contraseña; personal temporal sin capacitación | M6: Técnica | N6: LOPDP arts. 25 y 37 | O6: Filtro antispam del proveedor de correo | P6: Alta | Q6: Estimación preliminar: el phishing es el vector inicial más frecuente en el sector educativo (Ulven y Wangen, 2021) y la temporada de admisión incrementa la exposición; se esperan uno o más compromisos de cuenta por año sin MFA. | R6: Medio | S6: Alto | T6: Datos de identificación y contacto utilizables para fraude o suplantación. Agravante: incluye adolescentes (grupo vulnerable). | U6: 1 | V6: =IF(R6="","",INDEX(Listas!$B$2:$B$6,MIN(5,MATCH(R6,Listas!$B$2:$B$6,0)+IF(U6="",0,U6)))) -> Alto | W6: =IF(OR(P6="",V6=""),"",INDEX('Decisión'!$B$4:$F$8,MATCH(P6,'Decisión'!$A$4:$A$8,0),MATCH(V6,'Decisión'!$B$3:$F$3,0))) -> Muy alto | X6: Mitigar | Y6: 8.5 Autenticación multifactor; 6.3 Concienciación y formación; 5.18 Revisión de derechos de acceso; minimización de campos del formulario | Z6: Dirección de TI y Admisiones | AA6: 2 meses | AB6: Baja | AC6: Medio | AD6: =IF(OR(AB6="",AC6=""),"",INDEX('Decisión'!$B$4:$F$8,MATCH(AB6,'Decisión'!$A$4:$A$8,0),MATCH(AC6,'Decisión'!$B$3:$F$3,0))) -> Medio | AE6: =IF(W6="","",IF(OR(W6="Alto",W6="Muy alto"),IF(OR(E6="Sí",G6="Sí"),"Sí (obligatoria)","Valorar"),"Recomendada por defecto")) -> Sí (obligatoria) | AF6: =IF(AD6="","",IF(AC6="Muy alto","Requiere observaciones DPD/jurídico y aprobación de la máxima autoridad",IF(OR(AD6="Muy bajo",AD6="Bajo"),"Aceptable (registrar y monitorear)",IF(AD6="Medio","Tratar en plan anual o aceptación formal","No aceptable: tratamiento prioritario")))) -> Tratar en plan anual o aceptación formal | AG6: % de cuentas con MFA (meta: 100 %); tasa de clics en simulaciones de phishing (meta: < 5 %) | AH6: En tratamiento
A7: R-03 | B7: SP2. Admisión y nivelación | C7: Publicación de resultados de admisión | D7: Identificación (cédula); puntaje de admisión | E7: No | F7: Aspirantes evaluados (≈2 500 por periodo) | G7: Sí | H7: Portal web y redes sociales institucionales | I7: Licitud | J7: Responsable (falla organizacional) | K7: Publicación de listados nominales con cédula y puntaje | L7: Práctica heredada sin análisis de minimización | M7: Organizacional | N7: LOPDP art. 37; principios de la LOPDP | O7: Ninguno | P7: Media | Q7: Estimación preliminar: la práctica se repite en cada periodo, pero su materialización como exposición indebida depende de que el listado se difunda fuera del canal previsto; se estima un evento cada 1 a 2 años. | R7: Medio | S7: Medio | T7: Exposición pública del resultado académico vinculado a la identidad; posible estigmatización. Agravante: número masivo de titulares. | U7: 1 | V7: =IF(R7="","",INDEX(Listas!$B$2:$B$6,MIN(5,MATCH(R7,Listas!$B$2:$B$6,0)+IF(U7="",0,U7)))) -> Alto | W7: =IF(OR(P7="",V7=""),"",INDEX('Decisión'!$B$4:$F$8,MATCH(P7,'Decisión'!$A$4:$A$8,0),MATCH(V7,'Decisión'!$B$3:$F$3,0))) -> Alto | X7: Evitar | Y7: 8.11 Enmascaramiento de datos (publicar solo un código de postulante); consulta individual autenticada | Z7: Admisiones | AA7: Próximo periodo | AB7: Muy baja | AC7: Bajo | AD7: =IF(OR(AB7="",AC7=""),"",INDEX('Decisión'!$B$4:$F$8,MATCH(AB7,'Decisión'!$A$4:$A$8,0),MATCH(AC7,'Decisión'!$B$3:$F$3,0))) -> Muy bajo | AE7: =IF(W7="","",IF(OR(W7="Alto",W7="Muy alto"),IF(OR(E7="Sí",G7="Sí"),"Sí (obligatoria)","Valorar"),"Recomendada por defecto")) -> Sí (obligatoria) | AF7: =IF(AD7="","",IF(AC7="Muy alto","Requiere observaciones DPD/jurídico y aprobación de la máxima autoridad",IF(OR(AD7="Muy bajo",AD7="Bajo"),"Aceptable (registrar y monitorear)",IF(AD7="Medio","Tratar en plan anual o aceptación formal","No aceptable: tratamiento prioritario")))) -> Aceptable (registrar y monitorear) | AG7: N.º de listados nominales publicados por periodo (meta: 0) | AH7: En tratamiento
A8: R-04 | B8: SP1. Registro y postulación | C8: Uso de datos de aspirantes para campañas de difusión | D8: Identificación; contacto | E8: No | F8: Aspirantes (≈5 000 por año) | G8: Sí | H8: CRM de admisiones; correo masivo | I8: Licitud | J8: Responsable (falla organizacional) | K8: Cláusula de consentimiento genérica utilizada para finalidades comerciales | L8: Consentimiento no diferenciado por finalidad | M8: Jurídica | N8: LOPDP (bases de legitimación y consentimiento) | O8: Cláusula genérica en el formulario | P8: Muy alta | Q8: Estimación preliminar: el tratamiento sin base válida ocurre en cada envío de campañas, varias veces por año. | R8: Bajo | S8: Medio | T8: Comunicaciones no deseadas y pérdida de control sobre los datos. Agravante: número masivo de titulares. | U8: 1 | V8: =IF(R8="","",INDEX(Listas!$B$2:$B$6,MIN(5,MATCH(R8,Listas!$B$2:$B$6,0)+IF(U8="",0,U8)))) -> Medio | W8: =IF(OR(P8="",V8=""),"",INDEX('Decisión'!$B$4:$F$8,MATCH(P8,'Decisión'!$A$4:$A$8,0),MATCH(V8,'Decisión'!$B$3:$F$3,0))) -> Alto | X8: Mitigar | Y8: 5.34 Privacidad y protección de la información personal (consentimiento por finalidad y aviso de privacidad); 5.31 Requisitos legales | Z8: Área jurídica y Admisiones | AA8: 1 mes | AB8: Baja | AC8: Bajo | AD8: =IF(OR(AB8="",AC8=""),"",INDEX('Decisión'!$B$4:$F$8,MATCH(AB8,'Decisión'!$A$4:$A$8,0),MATCH(AC8,'Decisión'!$B$3:$F$3,0))) -> Bajo | AE8: =IF(W8="","",IF(OR(W8="Alto",W8="Muy alto"),IF(OR(E8="Sí",G8="Sí"),"Sí (obligatoria)","Valorar"),"Recomendada por defecto")) -> Sí (obligatoria) | AF8: =IF(AD8="","",IF(AC8="Muy alto","Requiere observaciones DPD/jurídico y aprobación de la máxima autoridad",IF(OR(AD8="Muy bajo",AD8="Bajo"),"Aceptable (registrar y monitorear)",IF(AD8="Medio","Tratar en plan anual o aceptación formal","No aceptable: tratamiento prioritario")))) -> Aceptable (registrar y monitorear) | AG8: % de registros de difusión con consentimiento específico (meta: 100 %) | AH8: En tratamiento
A9: R-05 | B9: SP5. Legalización de la matrícula | C9: Consulta y actualización del expediente en el SGA | D9: Expediente académico y personal completo | E9: No | F9: Estudiantes matriculados (≈6 000) | G9: No | H9: Sistema de gestión académica (SGA) | I9: Confidencialidad | J9: Personal interno o temporal | K9: Consultas sin necesidad de conocer con perfiles asignados por unidad | L9: Perfiles de acceso por unidad y no por función; sin revisión periódica | M9: Organizacional | N9: LOPDP art. 37 | O9: Usuario y contraseña por funcionario | P9: Alta | Q9: Estimación preliminar: con privilegios excesivos y sin registro de accesos, las consultas indebidas son previsibles varias veces por año, en especial con personal de temporada. | R9: Medio | S9: Medio | T9: Acceso indebido a datos personales y académicos; posible uso para fines no autorizados. | U9: 0 | V9: =IF(R9="","",INDEX(Listas!$B$2:$B$6,MIN(5,MATCH(R9,Listas!$B$2:$B$6,0)+IF(U9="",0,U9)))) -> Medio | W9: =IF(OR(P9="",V9=""),"",INDEX('Decisión'!$B$4:$F$8,MATCH(P9,'Decisión'!$A$4:$A$8,0),MATCH(V9,'Decisión'!$B$3:$F$3,0))) -> Alto | X9: Mitigar | Y9: 5.15 Control de acceso por función; 5.18 Revisión de derechos de acceso por periodo; 8.15 Registro de accesos | Z9: Secretaría Académica y Dirección de TI | AA9: 4 meses | AB9: Baja | AC9: Medio | AD9: =IF(OR(AB9="",AC9=""),"",INDEX('Decisión'!$B$4:$F$8,MATCH(AB9,'Decisión'!$A$4:$A$8,0),MATCH(AC9,'Decisión'!$B$3:$F$3,0))) -> Medio | AE9: =IF(W9="","",IF(OR(W9="Alto",W9="Muy alto"),IF(OR(E9="Sí",G9="Sí"),"Sí (obligatoria)","Valorar"),"Recomendada por defecto")) -> Valorar | AF9: =IF(AD9="","",IF(AC9="Muy alto","Requiere observaciones DPD/jurídico y aprobación de la máxima autoridad",IF(OR(AD9="Muy bajo",AD9="Bajo"),"Aceptable (registrar y monitorear)",IF(AD9="Medio","Tratar en plan anual o aceptación formal","No aceptable: tratamiento prioritario")))) -> Tratar en plan anual o aceptación formal | AG9: % de perfiles revisados al cierre de cada periodo (meta: 100 %) | AH9: Identificado
A10: R-06 | B10: SP2. Admisión y nivelación | C10: Registro de resultados de la prueba de admisión | D10: Puntajes; decisión de admisión | E10: No | F10: Aspirantes evaluados (≈2 500 por periodo) | G10: Sí | H10: Sistema de gestión académica (SGA) | I10: Integridad | J10: Interno malicioso o atacante externo | K10: Cuenta privilegiada comprometida | L10: Cuentas administrativas compartidas; sin registro de cambios | M10: Técnica | N10: LOPDP art. 37 | O10: Respaldo diario de la base de datos | P10: Baja | Q10: Estimación preliminar: requiere intención y acceso privilegiado; hay antecedentes en el sector, pero son poco frecuentes. | R10: Alto | S10: Alto | T10: Admisión o rechazo indebido: pérdida de oportunidades académicas difícil de revertir. | U10: 0 | V10: =IF(R10="","",INDEX(Listas!$B$2:$B$6,MIN(5,MATCH(R10,Listas!$B$2:$B$6,0)+IF(U10="",0,U10)))) -> Alto | W10: =IF(OR(P10="",V10=""),"",INDEX('Decisión'!$B$4:$F$8,MATCH(P10,'Decisión'!$A$4:$A$8,0),MATCH(V10,'Decisión'!$B$3:$F$3,0))) -> Alto | X10: Mitigar | Y10: 8.2 Derechos de acceso privilegiado (cuentas nominativas); 8.5 MFA; 8.15 Registro de cambios; segregación de funciones | Z10: Dirección de TI | AA10: 3 meses | AB10: Muy baja | AC10: Alto | AD10: =IF(OR(AB10="",AC10=""),"",INDEX('Decisión'!$B$4:$F$8,MATCH(AB10,'Decisión'!$A$4:$A$8,0),MATCH(AC10,'Decisión'!$B$3:$F$3,0))) -> Medio | AE10: =IF(W10="","",IF(OR(W10="Alto",W10="Muy alto"),IF(OR(E10="Sí",G10="Sí"),"Sí (obligatoria)","Valorar"),"Recomendada por defecto")) -> Sí (obligatoria) | AF10: =IF(AD10="","",IF(AC10="Muy alto","Requiere observaciones DPD/jurídico y aprobación de la máxima autoridad",IF(OR(AD10="Muy bajo",AD10="Bajo"),"Aceptable (registrar y monitorear)",IF(AD10="Medio","Tratar en plan anual o aceptación formal","No aceptable: tratamiento prioritario")))) -> Tratar en plan anual o aceptación formal | AG10: N.º de cambios de puntaje sin orden de trabajo (meta: 0) | AH10: Identificado
A11: R-07 | B11: SP4. Pago de matrícula | C11: Cobro de matrícula mediante pasarela de pagos | D11: Datos de facturación; datos de tarjeta o cuenta del pagador | E11: No | F11: Estudiantes y pagadores (≈6 000) | G11: No | H11: Pasarela de pagos (encargado) | I11: Confidencialidad | J11: Encargado del tratamiento; ciberdelincuencia | K11: Tratamiento por el proveedor sin obligaciones contractuales de protección de datos | L11: Contrato sin cláusulas de protección de datos ni de notificación de incidentes | M11: Jurídica | N11: LOPDP; normativa SPDP sobre encargados | O11: Proveedor declara cumplir estándares de la industria de pagos | P11: Baja | Q11: Estimación preliminar: los proveedores de pago suelen tener controles maduros; el riesgo proviene sobre todo de la falta de garantías contractuales. | R11: Alto | S11: Alto | T11: Fraude financiero a estudiantes y pagadores. | U11: 0 | V11: =IF(R11="","",INDEX(Listas!$B$2:$B$6,MIN(5,MATCH(R11,Listas!$B$2:$B$6,0)+IF(U11="",0,U11)))) -> Alto | W11: =IF(OR(P11="",V11=""),"",INDEX('Decisión'!$B$4:$F$8,MATCH(P11,'Decisión'!$A$4:$A$8,0),MATCH(V11,'Decisión'!$B$3:$F$3,0))) -> Alto | X11: Transferir | Y11: 5.19 y 5.20 Seguridad en relaciones y acuerdos con proveedores (cláusulas de protección de datos y notificación de incidentes) | Z11: Dirección Financiera y área jurídica | AA11: 6 meses | AB11: Muy baja | AC11: Alto | AD11: =IF(OR(AB11="",AC11=""),"",INDEX('Decisión'!$B$4:$F$8,MATCH(AB11,'Decisión'!$A$4:$A$8,0),MATCH(AC11,'Decisión'!$B$3:$F$3,0))) -> Medio | AE11: =IF(W11="","",IF(OR(W11="Alto",W11="Muy alto"),IF(OR(E11="Sí",G11="Sí"),"Sí (obligatoria)","Valorar"),"Recomendada por defecto")) -> Valorar | AF11: =IF(AD11="","",IF(AC11="Muy alto","Requiere observaciones DPD/jurídico y aprobación de la máxima autoridad",IF(OR(AD11="Muy bajo",AD11="Bajo"),"Aceptable (registrar y monitorear)",IF(AD11="Medio","Tratar en plan anual o aceptación formal","No aceptable: tratamiento prioritario")))) -> Tratar en plan anual o aceptación formal | AG11: % de encargados con cláusulas firmadas (meta: 100 %) | AH11: Identificado
A12: R-08 | B12: SP5. Legalización de la matrícula | C12: Operación del SGA durante el periodo de matrícula | D12: Expediente académico y personal completo | E12: No | F12: Estudiantes y aspirantes (≈8 500) | G12: No | H12: SGA y servidores de base de datos | I12: Disponibilidad | J12: Ciberdelincuencia organizada | K12: Ransomware tras compromiso de credenciales o vulnerabilidad sin parche | L12: Respaldos en línea accesibles desde la red; parcheo irregular | M12: Técnica | N12: LOPDP arts. 37 y 43 | O12: Antivirus; respaldo diario en el mismo entorno | P12: Media | Q12: Estimación preliminar: el 66 % de las IES encuestadas reportó un ataque de ransomware en el último año (Sophos, 2024); con controles parciales se estima un evento cada 1 a 2 años. | R12: Alto | S12: Muy alto | T12: Interrupción de la matrícula y pérdida de oportunidades académicas. Agravante: número masivo de titulares. | U12: 1 | V12: =IF(R12="","",INDEX(Listas!$B$2:$B$6,MIN(5,MATCH(R12,Listas!$B$2:$B$6,0)+IF(U12="",0,U12)))) -> Muy alto | W12: =IF(OR(P12="",V12=""),"",INDEX('Decisión'!$B$4:$F$8,MATCH(P12,'Decisión'!$A$4:$A$8,0),MATCH(V12,'Decisión'!$B$3:$F$3,0))) -> Muy alto | X12: Mitigar | Y12: 8.13 Copias de seguridad aisladas y probadas; 8.8 Gestión de vulnerabilidades técnicas; 8.7 Protección contra malware; 5.24 y 5.26 Respuesta a incidentes | Z12: Dirección de TI | AA12: 4 meses | AB12: Baja | AC12: Medio | AD12: =IF(OR(AB12="",AC12=""),"",INDEX('Decisión'!$B$4:$F$8,MATCH(AB12,'Decisión'!$A$4:$A$8,0),MATCH(AC12,'Decisión'!$B$3:$F$3,0))) -> Medio | AE12: =IF(W12="","",IF(OR(W12="Alto",W12="Muy alto"),IF(OR(E12="Sí",G12="Sí"),"Sí (obligatoria)","Valorar"),"Recomendada por defecto")) -> Valorar | AF12: =IF(AD12="","",IF(AC12="Muy alto","Requiere observaciones DPD/jurídico y aprobación de la máxima autoridad",IF(OR(AD12="Muy bajo",AD12="Bajo"),"Aceptable (registrar y monitorear)",IF(AD12="Medio","Tratar en plan anual o aceptación formal","No aceptable: tratamiento prioritario")))) -> Tratar en plan anual o aceptación formal | AG12: Tiempo de restauración en la prueba trimestral (meta: < 24 h); % de parches críticos aplicados en 15 días | AH12: Identificado
A13: R-09 | B13: SP3. Becas y aranceles diferenciados | C13: Almacenamiento de expedientes de becas en servidores institucionales | D13: Discapacidad y salud; socioeconómicos; identificación | E13: Sí | F13: Postulantes a beca y núcleo familiar (≈1 200) | G13: Sí | H13: Servidor de archivos y respaldos | I13: Confidencialidad | J13: Ciberdelincuencia organizada | K13: Exfiltración previa al cifrado en un ataque de ransomware (doble extorsión) | L13: Datos sensibles sin cifrado en reposo; sin monitoreo de salida de datos | M13: Técnica | N13: LOPDP arts. 25, 37, 40 y 43 | O13: Antivirus | P13: Media | Q13: Estimación preliminar: en el caso de la UTFSM (2024) se publicaron 14 GB de datos de estudiantes tras un ataque; la exfiltración acompaña con frecuencia al ransomware en el sector. | R13: Alto | S13: Muy alto | T13: Publicación de datos de discapacidad y socioeconómicos. Agravantes: categorías especiales y grupo vulnerable; vulneración intencional. | U13: 2 | V13: =IF(R13="","",INDEX(Listas!$B$2:$B$6,MIN(5,MATCH(R13,Listas!$B$2:$B$6,0)+IF(U13="",0,U13)))) -> Muy alto | W13: =IF(OR(P13="",V13=""),"",INDEX('Decisión'!$B$4:$F$8,MATCH(P13,'Decisión'!$A$4:$A$8,0),MATCH(V13,'Decisión'!$B$3:$F$3,0))) -> Muy alto | X13: Mitigar | Y13: 8.24 Cifrado en reposo; 8.12 Prevención de fuga; 8.16 Monitoreo de actividades; 8.10 Eliminación de lo que no se necesita | Z13: Dirección de TI y Bienestar Estudiantil | AA13: 6 meses | AB13: Baja | AC13: Muy alto | AD13: =IF(OR(AB13="",AC13=""),"",INDEX('Decisión'!$B$4:$F$8,MATCH(AB13,'Decisión'!$A$4:$A$8,0),MATCH(AC13,'Decisión'!$B$3:$F$3,0))) -> Alto | AE13: =IF(W13="","",IF(OR(W13="Alto",W13="Muy alto"),IF(OR(E13="Sí",G13="Sí"),"Sí (obligatoria)","Valorar"),"Recomendada por defecto")) -> Sí (obligatoria) | AF13: =IF(AD13="","",IF(AC13="Muy alto","Requiere observaciones DPD/jurídico y aprobación de la máxima autoridad",IF(OR(AD13="Muy bajo",AD13="Bajo"),"Aceptable (registrar y monitorear)",IF(AD13="Medio","Tratar en plan anual o aceptación formal","No aceptable: tratamiento prioritario")))) -> Requiere observaciones DPD/jurídico y aprobación de la máxima autoridad | AG13: % de repositorios sensibles cifrados (meta: 100 %); alertas de exfiltración atendidas en < 24 h | AH13: Identificado
A14: R-10 | B14: SP6. Reportes y archivo | C14: Conservación de expedientes de aspirantes no admitidos | D14: Identificación; académicos; en algunos casos socioeconómicos | E14: No | F14: Aspirantes no admitidos de periodos anteriores (≈10 000 acumulados) | G14: No | H14: SGA y repositorios de archivo | I14: Licitud | J14: Responsable (falla organizacional) | K14: Conservación indefinida sin finalidad vigente | L14: Ausencia de política de conservación y eliminación | M14: Jurídica | N14: LOPDP; Res. SPDP sobre anonimización y eliminación | O14: Ninguno | P14: Muy alta | Q14: Estimación preliminar: la conservación sin finalidad es una condición permanente que se renueva cada periodo. | R14: Bajo | S14: Medio | T14: Tratamiento sin finalidad y mayor superficie de exposición. Agravante: número masivo de titulares acumulados. | U14: 1 | V14: =IF(R14="","",INDEX(Listas!$B$2:$B$6,MIN(5,MATCH(R14,Listas!$B$2:$B$6,0)+IF(U14="",0,U14)))) -> Medio | W14: =IF(OR(P14="",V14=""),"",INDEX('Decisión'!$B$4:$F$8,MATCH(P14,'Decisión'!$A$4:$A$8,0),MATCH(V14,'Decisión'!$B$3:$F$3,0))) -> Alto | X14: Mitigar | Y14: 8.10 Eliminación de la información (tabla de conservación y eliminación periódica); 5.9 Inventario | Z14: Secretaría Académica y área jurídica | AA14: 6 meses | AB14: Muy baja | AC14: Bajo | AD14: =IF(OR(AB14="",AC14=""),"",INDEX('Decisión'!$B$4:$F$8,MATCH(AB14,'Decisión'!$A$4:$A$8,0),MATCH(AC14,'Decisión'!$B$3:$F$3,0))) -> Muy bajo | AE14: =IF(W14="","",IF(OR(W14="Alto",W14="Muy alto"),IF(OR(E14="Sí",G14="Sí"),"Sí (obligatoria)","Valorar"),"Recomendada por defecto")) -> Valorar | AF14: =IF(AD14="","",IF(AC14="Muy alto","Requiere observaciones DPD/jurídico y aprobación de la máxima autoridad",IF(OR(AD14="Muy bajo",AD14="Bajo"),"Aceptable (registrar y monitorear)",IF(AD14="Medio","Tratar en plan anual o aceptación formal","No aceptable: tratamiento prioritario")))) -> Aceptable (registrar y monitorear) | AG14: N.º de expedientes vencidos sin eliminar (meta: 0) | AH14: Identificado
A15: R-11 | B15: SP3. Becas y aranceles diferenciados | C15: Uso de formularios y almacenamiento en la nube de un proveedor extranjero | D15: Discapacidad y salud; socioeconómicos | E15: Sí | F15: Postulantes a beca (≈1 200) | G15: Sí | H15: Suite de productividad en la nube | I15: Licitud | J15: Responsable (falla organizacional) | K15: Transferencia internacional sin evaluación de garantías | L15: No se ha evaluado la transferencia ni se han revisado las condiciones del proveedor | M15: Jurídica | N15: LOPDP; normativa SPDP sobre transferencias | O15: Términos de servicio estándar del proveedor | P15: Media | Q15: Estimación preliminar: la transferencia es continua, pero la materialización del daño depende de un uso indebido o de un requerimiento extranjero, poco frecuente. | R15: Medio | S15: Medio | T15: Pérdida de control sobre datos sensibles. Agravante: categorías especiales. | U15: 1 | V15: =IF(R15="","",INDEX(Listas!$B$2:$B$6,MIN(5,MATCH(R15,Listas!$B$2:$B$6,0)+IF(U15="",0,U15)))) -> Alto | W15: =IF(OR(P15="",V15=""),"",INDEX('Decisión'!$B$4:$F$8,MATCH(P15,'Decisión'!$A$4:$A$8,0),MATCH(V15,'Decisión'!$B$3:$F$3,0))) -> Alto | X15: Mitigar | Y15: 5.19 y 5.20 Acuerdos con proveedores; 5.31 Requisitos legales (evaluación de la transferencia) | Z15: Área jurídica y Dirección de TI | AA15: 4 meses | AB15: Baja | AC15: Medio | AD15: =IF(OR(AB15="",AC15=""),"",INDEX('Decisión'!$B$4:$F$8,MATCH(AB15,'Decisión'!$A$4:$A$8,0),MATCH(AC15,'Decisión'!$B$3:$F$3,0))) -> Medio | AE15: =IF(W15="","",IF(OR(W15="Alto",W15="Muy alto"),IF(OR(E15="Sí",G15="Sí"),"Sí (obligatoria)","Valorar"),"Recomendada por defecto")) -> Sí (obligatoria) | AF15: =IF(AD15="","",IF(AC15="Muy alto","Requiere observaciones DPD/jurídico y aprobación de la máxima autoridad",IF(OR(AD15="Muy bajo",AD15="Bajo"),"Aceptable (registrar y monitorear)",IF(AD15="Medio","Tratar en plan anual o aceptación formal","No aceptable: tratamiento prioritario")))) -> Tratar en plan anual o aceptación formal | AG15: % de servicios en la nube con evaluación de transferencia (meta: 100 %) | AH15: Identificado
A16: R-12 | B16: SP6. Reportes y archivo | C16: Gestión de vulneraciones de seguridad que afectan datos del proceso | D16: Todas las del proceso | E16: Sí | F16: Estudiantes y aspirantes (≈8 500) | G16: Sí | H16: Procesos de respuesta a incidentes | I16: Licitud | J16: Responsable (falla organizacional) | K16: Vulneración no detectada o notificada fuera del término legal | L16: Sin procedimiento documentado de gestión y notificación de vulneraciones | M16: Organizacional | N16: LOPDP art. 43 | O16: Mesa de ayuda de TI | P16: Media | Q16: Estimación preliminar: depende de la ocurrencia de un incidente (R-01, R-08, R-09); sin procedimiento, la notificación tardía es probable ante cualquiera de ellos. | R16: Medio | S16: Alto | T16: Los titulares no reciben información a tiempo para protegerse. | U16: 0 | V16: =IF(R16="","",INDEX(Listas!$B$2:$B$6,MIN(5,MATCH(R16,Listas!$B$2:$B$6,0)+IF(U16="",0,U16)))) -> Medio | W16: =IF(OR(P16="",V16=""),"",INDEX('Decisión'!$B$4:$F$8,MATCH(P16,'Decisión'!$A$4:$A$8,0),MATCH(V16,'Decisión'!$B$3:$F$3,0))) -> Medio | X16: Mitigar | Y16: 5.24 Planificación de la gestión de incidentes; 5.26 Respuesta; simulacro anual | Z16: Dirección de TI y delegado de protección de datos | AA16: 2 meses | AB16: Baja | AC16: Bajo | AD16: =IF(OR(AB16="",AC16=""),"",INDEX('Decisión'!$B$4:$F$8,MATCH(AB16,'Decisión'!$A$4:$A$8,0),MATCH(AC16,'Decisión'!$B$3:$F$3,0))) -> Bajo | AE16: =IF(W16="","",IF(OR(W16="Alto",W16="Muy alto"),IF(OR(E16="Sí",G16="Sí"),"Sí (obligatoria)","Valorar"),"Recomendada por defecto")) -> Recomendada por defecto | AF16: =IF(AD16="","",IF(AC16="Muy alto","Requiere observaciones DPD/jurídico y aprobación de la máxima autoridad",IF(OR(AD16="Muy bajo",AD16="Bajo"),"Aceptable (registrar y monitorear)",IF(AD16="Medio","Tratar en plan anual o aceptación formal","No aceptable: tratamiento prioritario")))) -> Aceptable (registrar y monitorear) | AG16: % de vulneraciones notificadas dentro del término (meta: 100 %); simulacro anual realizado | AH16: Identificado
A17: R-13 | B17: SP1. Registro y postulación | C17: Recepción de postulaciones en línea | D17: Identificación; contacto | E17: No | F17: Aspirantes (≈2 500 por periodo) | G17: No | H17: Portal web de postulación | I17: Disponibilidad | J17: Fallas técnicas; ataque de denegación de servicio | K17: Saturación del portal en el cierre de postulaciones | L17: Capacidad no dimensionada para picos de demanda | M17: Técnica | N17: LOPDP art. 37 | O17: Monitoreo básico del servidor | P17: Media | Q17: Estimación preliminar: los picos de demanda se producen en cada cierre de postulación (dos por año) y han causado indisponibilidad parcial. | R17: Bajo | S17: Medio | T17: Retrasos en la postulación, superables con ampliación de plazos. | U17: 0 | V17: =IF(R17="","",INDEX(Listas!$B$2:$B$6,MIN(5,MATCH(R17,Listas!$B$2:$B$6,0)+IF(U17="",0,U17)))) -> Bajo | W17: =IF(OR(P17="",V17=""),"",INDEX('Decisión'!$B$4:$F$8,MATCH(P17,'Decisión'!$A$4:$A$8,0),MATCH(V17,'Decisión'!$B$3:$F$3,0))) -> Medio | X17: Mitigar | Y17: 8.6 Gestión de la capacidad; acuerdo de nivel de servicio con el proveedor de alojamiento | Z17: Dirección de TI | AA17: Próximo periodo | AB17: Baja | AC17: Bajo | AD17: =IF(OR(AB17="",AC17=""),"",INDEX('Decisión'!$B$4:$F$8,MATCH(AB17,'Decisión'!$A$4:$A$8,0),MATCH(AC17,'Decisión'!$B$3:$F$3,0))) -> Bajo | AE17: =IF(W17="","",IF(OR(W17="Alto",W17="Muy alto"),IF(OR(E17="Sí",G17="Sí"),"Sí (obligatoria)","Valorar"),"Recomendada por defecto")) -> Recomendada por defecto | AF17: =IF(AD17="","",IF(AC17="Muy alto","Requiere observaciones DPD/jurídico y aprobación de la máxima autoridad",IF(OR(AD17="Muy bajo",AD17="Bajo"),"Aceptable (registrar y monitorear)",IF(AD17="Medio","Tratar en plan anual o aceptación formal","No aceptable: tratamiento prioritario")))) -> Aceptable (registrar y monitorear) | AG17: Disponibilidad del portal en la semana de cierre (meta: ≥ 99 %) | AH17: Identificado
V18: =IF(R18="","",INDEX(Listas!$B$2:$B$6,MIN(5,MATCH(R18,Listas!$B$2:$B$6,0)+IF(U18="",0,U18)))) | W18: =IF(OR(P18="",V18=""),"",INDEX('Decisión'!$B$4:$F$8,MATCH(P18,'Decisión'!$A$4:$A$8,0),MATCH(V18,'Decisión'!$B$3:$F$3,0))) | AD18: =IF(OR(AB18="",AC18=""),"",INDEX('Decisión'!$B$4:$F$8,MATCH(AB18,'Decisión'!$A$4:$A$8,0),MATCH(AC18,'Decisión'!$B$3:$F$3,0))) | AE18: =IF(W18="","",IF(OR(W18="Alto",W18="Muy alto"),IF(OR(E18="Sí",G18="Sí"),"Sí (obligatoria)","Valorar"),"Recomendada por defecto")) | AF18: =IF(AD18="","",IF(AC18="Muy alto","Requiere observaciones DPD/jurídico y aprobación de la máxima autoridad",IF(OR(AD18="Muy bajo",AD18="Bajo"),"Aceptable (registrar y monitorear)",IF(AD18="Medio","Tratar en plan anual o aceptación formal","No aceptable: tratamiento prioritario"))))
V19: =IF(R19="","",INDEX(Listas!$B$2:$B$6,MIN(5,MATCH(R19,Listas!$B$2:$B$6,0)+IF(U19="",0,U19)))) | W19: =IF(OR(P19="",V19=""),"",INDEX('Decisión'!$B$4:$F$8,MATCH(P19,'Decisión'!$A$4:$A$8,0),MATCH(V19,'Decisión'!$B$3:$F$3,0))) | AD19: =IF(OR(AB19="",AC19=""),"",INDEX('Decisión'!$B$4:$F$8,MATCH(AB19,'Decisión'!$A$4:$A$8,0),MATCH(AC19,'Decisión'!$B$3:$F$3,0))) | AE19: =IF(W19="","",IF(OR(W19="Alto",W19="Muy alto"),IF(OR(E19="Sí",G19="Sí"),"Sí (obligatoria)","Valorar"),"Recomendada por defecto")) | AF19: =IF(AD19="","",IF(AC19="Muy alto","Requiere observaciones DPD/jurídico y aprobación de la máxima autoridad",IF(OR(AD19="Muy bajo",AD19="Bajo"),"Aceptable (registrar y monitorear)",IF(AD19="Medio","Tratar en plan anual o aceptación formal","No aceptable: tratamiento prioritario"))))
V20: =IF(R20="","",INDEX(Listas!$B$2:$B$6,MIN(5,MATCH(R20,Listas!$B$2:$B$6,0)+IF(U20="",0,U20)))) | W20: =IF(OR(P20="",V20=""),"",INDEX('Decisión'!$B$4:$F$8,MATCH(P20,'Decisión'!$A$4:$A$8,0),MATCH(V20,'Decisión'!$B$3:$F$3,0))) | AD20: =IF(OR(AB20="",AC20=""),"",INDEX('Decisión'!$B$4:$F$8,MATCH(AB20,'Decisión'!$A$4:$A$8,0),MATCH(AC20,'Decisión'!$B$3:$F$3,0))) | AE20: =IF(W20="","",IF(OR(W20="Alto",W20="Muy alto"),IF(OR(E20="Sí",G20="Sí"),"Sí (obligatoria)","Valorar"),"Recomendada por defecto")) | AF20: =IF(AD20="","",IF(AC20="Muy alto","Requiere observaciones DPD/jurídico y aprobación de la máxima autoridad",IF(OR(AD20="Muy bajo",AD20="Bajo"),"Aceptable (registrar y monitorear)",IF(AD20="Medio","Tratar en plan anual o aceptación formal","No aceptable: tratamiento prioritario"))))
V21: =IF(R21="","",INDEX(Listas!$B$2:$B$6,MIN(5,MATCH(R21,Listas!$B$2:$B$6,0)+IF(U21="",0,U21)))) | W21: =IF(OR(P21="",V21=""),"",INDEX('Decisión'!$B$4:$F$8,MATCH(P21,'Decisión'!$A$4:$A$8,0),MATCH(V21,'Decisión'!$B$3:$F$3,0))) | AD21: =IF(OR(AB21="",AC21=""),"",INDEX('Decisión'!$B$4:$F$8,MATCH(AB21,'Decisión'!$A$4:$A$8,0),MATCH(AC21,'Decisión'!$B$3:$F$3,0))) | AE21: =IF(W21="","",IF(OR(W21="Alto",W21="Muy alto"),IF(OR(E21="Sí",G21="Sí"),"Sí (obligatoria)","Valorar"),"Recomendada por defecto")) | AF21: =IF(AD21="","",IF(AC21="Muy alto","Requiere observaciones DPD/jurídico y aprobación de la máxima autoridad",IF(OR(AD21="Muy bajo",AD21="Bajo"),"Aceptable (registrar y monitorear)",IF(AD21="Medio","Tratar en plan anual o aceptación formal","No aceptable: tratamiento prioritario"))))
V22: =IF(R22="","",INDEX(Listas!$B$2:$B$6,MIN(5,MATCH(R22,Listas!$B$2:$B$6,0)+IF(U22="",0,U22)))) | W22: =IF(OR(P22="",V22=""),"",INDEX('Decisión'!$B$4:$F$8,MATCH(P22,'Decisión'!$A$4:$A$8,0),MATCH(V22,'Decisión'!$B$3:$F$3,0))) | AD22: =IF(OR(AB22="",AC22=""),"",INDEX('Decisión'!$B$4:$F$8,MATCH(AB22,'Decisión'!$A$4:$A$8,0),MATCH(AC22,'Decisión'!$B$3:$F$3,0))) | AE22: =IF(W22="","",IF(OR(W22="Alto",W22="Muy alto"),IF(OR(E22="Sí",G22="Sí"),"Sí (obligatoria)","Valorar"),"Recomendada por defecto")) | AF22: =IF(AD22="","",IF(AC22="Muy alto","Requiere observaciones DPD/jurídico y aprobación de la máxima autoridad",IF(OR(AD22="Muy bajo",AD22="Bajo"),"Aceptable (registrar y monitorear)",IF(AD22="Medio","Tratar en plan anual o aceptación formal","No aceptable: tratamiento prioritario"))))
V23: =IF(R23="","",INDEX(Listas!$B$2:$B$6,MIN(5,MATCH(R23,Listas!$B$2:$B$6,0)+IF(U23="",0,U23)))) | W23: =IF(OR(P23="",V23=""),"",INDEX('Decisión'!$B$4:$F$8,MATCH(P23,'Decisión'!$A$4:$A$8,0),MATCH(V23,'Decisión'!$B$3:$F$3,0))) | AD23: =IF(OR(AB23="",AC23=""),"",INDEX('Decisión'!$B$4:$F$8,MATCH(AB23,'Decisión'!$A$4:$A$8,0),MATCH(AC23,'Decisión'!$B$3:$F$3,0))) | AE23: =IF(W23="","",IF(OR(W23="Alto",W23="Muy alto"),IF(OR(E23="Sí",G23="Sí"),"Sí (obligatoria)","Valorar"),"Recomendada por defecto")) | AF23: =IF(AD23="","",IF(AC23="Muy alto","Requiere observaciones DPD/jurídico y aprobación de la máxima autoridad",IF(OR(AD23="Muy bajo",AD23="Bajo"),"Aceptable (registrar y monitorear)",IF(AD23="Medio","Tratar en plan anual o aceptación formal","No aceptable: tratamiento prioritario"))))
V24: =IF(R24="","",INDEX(Listas!$B$2:$B$6,MIN(5,MATCH(R24,Listas!$B$2:$B$6,0)+IF(U24="",0,U24)))) | W24: =IF(OR(P24="",V24=""),"",INDEX('Decisión'!$B$4:$F$8,MATCH(P24,'Decisión'!$A$4:$A$8,0),MATCH(V24,'Decisión'!$B$3:$F$3,0))) | AD24: =IF(OR(AB24="",AC24=""),"",INDEX('Decisión'!$B$4:$F$8,MATCH(AB24,'Decisión'!$A$4:$A$8,0),MATCH(AC24,'Decisión'!$B$3:$F$3,0))) | AE24: =IF(W24="","",IF(OR(W24="Alto",W24="Muy alto"),IF(OR(E24="Sí",G24="Sí"),"Sí (obligatoria)","Valorar"),"Recomendada por defecto")) | AF24: =IF(AD24="","",IF(AC24="Muy alto","Requiere observaciones DPD/jurídico y aprobación de la máxima autoridad",IF(OR(AD24="Muy bajo",AD24="Bajo"),"Aceptable (registrar y monitorear)",IF(AD24="Medio","Tratar en plan anual o aceptación formal","No aceptable: tratamiento prioritario"))))
V25: =IF(R25="","",INDEX(Listas!$B$2:$B$6,MIN(5,MATCH(R25,Listas!$B$2:$B$6,0)+IF(U25="",0,U25)))) | W25: =IF(OR(P25="",V25=""),"",INDEX('Decisión'!$B$4:$F$8,MATCH(P25,'Decisión'!$A$4:$A$8,0),MATCH(V25,'Decisión'!$B$3:$F$3,0))) | AD25: =IF(OR(AB25="",AC25=""),"",INDEX('Decisión'!$B$4:$F$8,MATCH(AB25,'Decisión'!$A$4:$A$8,0),MATCH(AC25,'Decisión'!$B$3:$F$3,0))) | AE25: =IF(W25="","",IF(OR(W25="Alto",W25="Muy alto"),IF(OR(E25="Sí",G25="Sí"),"Sí (obligatoria)","Valorar"),"Recomendada por defecto")) | AF25: =IF(AD25="","",IF(AC25="Muy alto","Requiere observaciones DPD/jurídico y aprobación de la máxima autoridad",IF(OR(AD25="Muy bajo",AD25="Bajo"),"Aceptable (registrar y monitorear)",IF(AD25="Medio","Tratar en plan anual o aceptación formal","No aceptable: tratamiento prioritario"))))
V26: =IF(R26="","",INDEX(Listas!$B$2:$B$6,MIN(5,MATCH(R26,Listas!$B$2:$B$6,0)+IF(U26="",0,U26)))) | W26: =IF(OR(P26="",V26=""),"",INDEX('Decisión'!$B$4:$F$8,MATCH(P26,'Decisión'!$A$4:$A$8,0),MATCH(V26,'Decisión'!$B$3:$F$3,0))) | AD26: =IF(OR(AB26="",AC26=""),"",INDEX('Decisión'!$B$4:$F$8,MATCH(AB26,'Decisión'!$A$4:$A$8,0),MATCH(AC26,'Decisión'!$B$3:$F$3,0))) | AE26: =IF(W26="","",IF(OR(W26="Alto",W26="Muy alto"),IF(OR(E26="Sí",G26="Sí"),"Sí (obligatoria)","Valorar"),"Recomendada por defecto")) | AF26: =IF(AD26="","",IF(AC26="Muy alto","Requiere observaciones DPD/jurídico y aprobación de la máxima autoridad",IF(OR(AD26="Muy bajo",AD26="Bajo"),"Aceptable (registrar y monitorear)",IF(AD26="Medio","Tratar en plan anual o aceptación formal","No aceptable: tratamiento prioritario"))))
V27: =IF(R27="","",INDEX(Listas!$B$2:$B$6,MIN(5,MATCH(R27,Listas!$B$2:$B$6,0)+IF(U27="",0,U27)))) | W27: =IF(OR(P27="",V27=""),"",INDEX('Decisión'!$B$4:$F$8,MATCH(P27,'Decisión'!$A$4:$A$8,0),MATCH(V27,'Decisión'!$B$3:$F$3,0))) | AD27: =IF(OR(AB27="",AC27=""),"",INDEX('Decisión'!$B$4:$F$8,MATCH(AB27,'Decisión'!$A$4:$A$8,0),MATCH(AC27,'Decisión'!$B$3:$F$3,0))) | AE27: =IF(W27="","",IF(OR(W27="Alto",W27="Muy alto"),IF(OR(E27="Sí",G27="Sí"),"Sí (obligatoria)","Valorar"),"Recomendada por defecto")) | AF27: =IF(AD27="","",IF(AC27="Muy alto","Requiere observaciones DPD/jurídico y aprobación de la máxima autoridad",IF(OR(AD27="Muy bajo",AD27="Bajo"),"Aceptable (registrar y monitorear)",IF(AD27="Medio","Tratar en plan anual o aceptación formal","No aceptable: tratamiento prioritario"))))
V28: =IF(R28="","",INDEX(Listas!$B$2:$B$6,MIN(5,MATCH(R28,Listas!$B$2:$B$6,0)+IF(U28="",0,U28)))) | W28: =IF(OR(P28="",V28=""),"",INDEX('Decisión'!$B$4:$F$8,MATCH(P28,'Decisión'!$A$4:$A$8,0),MATCH(V28,'Decisión'!$B$3:$F$3,0))) | AD28: =IF(OR(AB28="",AC28=""),"",INDEX('Decisión'!$B$4:$F$8,MATCH(AB28,'Decisión'!$A$4:$A$8,0),MATCH(AC28,'Decisión'!$B$3:$F$3,0))) | AE28: =IF(W28="","",IF(OR(W28="Alto",W28="Muy alto"),IF(OR(E28="Sí",G28="Sí"),"Sí (obligatoria)","Valorar"),"Recomendada por defecto")) | AF28: =IF(AD28="","",IF(AC28="Muy alto","Requiere observaciones DPD/jurídico y aprobación de la máxima autoridad",IF(OR(AD28="Muy bajo",AD28="Bajo"),"Aceptable (registrar y monitorear)",IF(AD28="Medio","Tratar en plan anual o aceptación formal","No aceptable: tratamiento prioritario"))))
V29: =IF(R29="","",INDEX(Listas!$B$2:$B$6,MIN(5,MATCH(R29,Listas!$B$2:$B$6,0)+IF(U29="",0,U29)))) | W29: =IF(OR(P29="",V29=""),"",INDEX('Decisión'!$B$4:$F$8,MATCH(P29,'Decisión'!$A$4:$A$8,0),MATCH(V29,'Decisión'!$B$3:$F$3,0))) | AD29: =IF(OR(AB29="",AC29=""),"",INDEX('Decisión'!$B$4:$F$8,MATCH(AB29,'Decisión'!$A$4:$A$8,0),MATCH(AC29,'Decisión'!$B$3:$F$3,0))) | AE29: =IF(W29="","",IF(OR(W29="Alto",W29="Muy alto"),IF(OR(E29="Sí",G29="Sí"),"Sí (obligatoria)","Valorar"),"Recomendada por defecto")) | AF29: =IF(AD29="","",IF(AC29="Muy alto","Requiere observaciones DPD/jurídico y aprobación de la máxima autoridad",IF(OR(AD29="Muy bajo",AD29="Bajo"),"Aceptable (registrar y monitorear)",IF(AD29="Medio","Tratar en plan anual o aceptación formal","No aceptable: tratamiento prioritario"))))
... V104: =IF(R104="","",INDEX(Listas!$B$2:$B$6,MIN(5,MATCH(R104,Listas!$B$2:$B$6,0)+IF(U104="",0,U104)))) | W104: =IF(OR(P104="",V104=""),"",INDEX('Decisión'!$B$4:$F$8,MATCH(P104,'Decisión'!$A$4:$A$8,0),MATCH(V104,'Decisión'!$B$3:$F$3,0))) | AD104: =IF(OR(AB104="",AC104=""),"",INDEX('Decisión'!$B$4:$F$8,MATCH(AB104,'Decisión'!$A$4:$A$8,0),MATCH(AC104,'Decisión'!$B$3:$F$3,0))) | AE104: =IF(W104="","",IF(OR(W104="Alto",W104="Muy alto"),IF(OR(E104="Sí",G104="Sí"),"Sí (obligatoria)","Valorar"),"Recomendada por defecto")) | AF104: =IF(AD104="","",IF(AC104="Muy alto","Requiere observaciones DPD/jurídico y aprobación de la máxima autoridad",IF(OR(AD104="Muy bajo",AD104="Bajo"),"Aceptable (registrar y monitorear)",IF(AD104="Medio","Tratar en plan anual o aceptación formal","No aceptable: tratamiento prioritario"))))

Sheet Decisión
A1: Tabla de decisión del nivel de riesgo
A2: El nivel se asigna por tabla, no por multiplicación (guía SPDP V.2). Impacto muy alto ⇒ nivel mínimo alto.
A3: Probabilidad / Impacto | B3: Muy bajo | C3: Bajo | D3: Medio | E3: Alto | F3: Muy alto
A4: Muy alta | B4: Medio | C4: Alto | D4: Alto | E4: Muy alto | F4: Muy alto
A5: Alta | B5: Bajo | C5: Medio | D5: Alto | E5: Muy alto | F5: Muy alto
A6: Media | B6: Bajo | C6: Medio | D6: Medio | E6: Alto | F6: Muy alto
A7: Baja | B7: Muy bajo | C7: Bajo | D7: Medio | E7: Alto | F7: Alto
A8: Muy baja | B8: Muy bajo | C8: Muy bajo | D8: Bajo | E8: Medio | F8: Alto
A10: Criterios de aceptación del riesgo
A11: Nivel | B11: Criterio
A12: Muy bajo | B12: Aceptable. Registrar la decisión y monitorear periódicamente.
A13: Bajo | B13: Aceptable. Registrar la decisión y monitorear periódicamente.
A14: Medio | B14: Tratar dentro del plan anual, salvo aceptación formal y justificada de la dirección.
A15: Alto | B15: Tratamiento prioritario. Si afecta categorías especiales o tratamiento a gran escala, activar EIPD (art. 42 LOPDP).
A16: Muy alto | B16: Tratamiento prioritario y EIPD. Con impacto muy alto sobre el titular, no puede aceptarse sin observaciones del DPD y del área jurídica y aprobación de la máxima autoridad.
A18: Fuente: Capítulo 2, Tablas de decisión y criterios de aceptación; Guía SPDP V.2 (Res. SPDP-SPD-2026-0012-R).

Sheet Escalas
A1: Escalas de probabilidad e impacto
A2: Versión inicial propuesta en el Capítulo 2; se calibra con el panel Delphi antes de aplicarla.
A4: Probabilidad (lapso anual)
A5: Nivel | B5: Valor ordinal | C5: Frecuencia anual esperada | D5: Descripción orientativa
A6: Muy baja | B6: 1 | C6: Menos de una vez cada 10 años | D6: Sin antecedentes en la institución ni en el sector; la amenaza requiere capacidades poco comunes.
A7: Baja | B7: 2 | C7: Una vez cada 2 a 10 años | D7: Antecedentes en el sector, pero los controles existentes dificultan su materialización.
A8: Media | B8: 3 | C8: Aproximadamente una vez cada 1 a 2 años | D8: Antecedentes en IES similares y controles parciales.
A9: Alta | B9: 4 | C9: Entre 1 y 5 veces por año | D9: El evento ha ocurrido en la institución o la vulnerabilidad es conocida y explotable.
A10: Muy alta | B10: 5 | C10: Más de 5 veces por año | D10: El evento es recurrente o la vulnerabilidad se explota con facilidad.
A12: Impacto sobre el titular (adaptado de ENISA, 2013)
A13: Nivel | B13: Valor ordinal | C13: Consecuencias para el titular
A14: Muy bajo | B14: 1 | C14: Molestias menores que el titular supera sin dificultad (por ejemplo, reingresar información).
A15: Bajo | B15: 2 | C15: Inconvenientes que el titular supera con algún esfuerzo (costos menores, tiempo, molestias).
A16: Medio | B16: 3 | C16: Consecuencias significativas que puede superar con dificultad (pérdida de oportunidades académicas, cargos indebidos reversibles, temor o estrés).
A17: Alto | B17: 4 | C17: Consecuencias graves, difíciles de superar (fraude o suplantación de identidad, discriminación, exclusión de beneficios, daño reputacional).
A18: Muy alto | B18: 5 | C18: Consecuencias irreversibles o que afectan derechos fundamentales, la salud o la integridad (exposición de datos de salud o discapacidad, afectación a menores de edad).
A20: Impacto sobre el responsable (perspectiva secundaria)
A21: Nivel | B21: Valor ordinal | C21: Consecuencias para la institución
A22: Muy bajo | B22: 1 | C22: Sin consecuencias legales ni económicas relevantes.
A23: Bajo | B23: 2 | C23: Requerimiento u observación de la autoridad sin sanción; costos de respuesta menores.
A24: Medio | B24: 3 | C24: Medidas correctivas ordenadas por la SPDP; costos de respuesta moderados; cobertura mediática local.
A25: Alto | B25: 4 | C25: Sanción administrativa; costos de respuesta significativos; afectación reputacional nacional.
A26: Muy alto | B26: 5 | C26: Sanción por infracción grave (art. 72 LOPDP); interrupción del servicio académico; pérdida de confianza masiva.
A28: Criterios agravantes del impacto (cada uno suma un nivel; máximo: Muy alto)
A29: Criterio | B29: Fundamento | C29: Ejemplo en matrícula
A30: Categorías especiales de datos o grupos vulnerables (incluidos adolescentes) | B30: LOPDP art. 25; guía SPDP | C30: Certificados de discapacidad; aspirantes menores de edad
A31: Número de titulares afectados superior al umbral masivo definido por la institución | B31: Guía SPDP | C31: Base completa de aspirantes del periodo
A32: Vulneración intencional o datos combinables que facilitan la identificación | B32: Guía SPDP; ENISA (2013) | C32: Exfiltración por atacante con cédula + datos socioeconómicos

Sheet Amenazas
A1: Catálogo de amenazas (proceso de admisión y matrícula)
A2: Punto de partida; ampliar en la fase de identificación.
A4: ID | B4: Amenaza | C4: Comunidad de amenaza | D4: Vector típico | E4: Dimensiones | F4: Subprocesos
A5: AM-01 | B5: Phishing y robo de credenciales institucionales | C5: Ciberdelincuencia organizada | D5: Correo fraudulento dirigido al personal de admisiones | E5: C, I | F5: SP1–SP5
A6: AM-02 | B6: Ransomware | C6: Ciberdelincuencia organizada | D6: Credenciales comprometidas; vulnerabilidades sin parche | E6: C, I, D | F6: Todos
A7: AM-03 | B7: Acceso indebido por privilegios excesivos | C7: Personal interno o temporal | D7: Perfiles por unidad y no por función en el SGA | E7: C | F7: SP2, SP3, SP5
A8: AM-04 | B8: Exposición por enlaces o carpetas compartidas | C8: Personal interno (error humano) | D8: Enlace "cualquiera con el enlace" en la nube | E8: C | F8: SP3, SP6
A9: AM-05 | B9: Publicación de listados con datos personales | C9: Personal interno (error humano) | D9: Listas de admitidos con cédula y calificaciones en canales públicos | E9: C, Licitud | F9: SP2
A10: AM-06 | B10: Tratamiento por proveedor sin garantías contractuales | C10: Encargados (proveedores SaaS) | D10: Contrato sin cláusulas de protección de datos | E10: C, Licitud | F10: SP1, SP4, SP5
A11: AM-07 | B11: Conservación indefinida de expedientes | C11: Responsable (falla organizacional) | D11: Ausencia de política de conservación y eliminación | E11: Licitud, C | F11: SP6
A12: AM-08 | B12: Uso de datos para finalidades no informadas | C12: Responsable (falla organizacional) | D12: Consentimiento genérico usado para marketing | E12: Licitud | F12: SP1
A13: AM-09 | B13: Fraude en pagos o suplantación del pagador | C13: Ciberdelincuencia | D13: Manipulación de comprobantes; compromiso de la pasarela | E13: C, I | F13: SP4
A14: AM-10 | B14: Alteración de calificaciones o resultados de admisión | C14: Interno malicioso o atacante externo | D14: Cuenta privilegiada comprometida | E14: I | F14: SP2
A15: AM-11 | B15: Indisponibilidad del portal en el periodo de postulación | C15: Fallas técnicas o ataque de denegación de servicio | D15: Saturación; fallo del proveedor | E15: D | F15: SP1, SP4
A16: AM-12 | B16: Pérdida de documentación por falta de respaldo | C16: Fallas técnicas o error humano | D16: Borrado accidental sin copia de seguridad | E16: D, I | F16: SP3, SP5

Sheet Controles
A1: Catálogo de controles (referencia ISO/IEC 27002:2022)
A2: Controles candidatos para el tratamiento de riesgos del proceso de matrícula.
A4: Ref. ISO/IEC 27002:2022 | B4: Control | C4: Tipo | D4: Aplicación en el proceso de matrícula
A5: 5.1 | B5: Políticas de seguridad de la información | C5: Organizacional | D5: Política de protección de datos del proceso de admisión
A6: 5.9 | B6: Inventario de información y otros activos asociados | C6: Organizacional | D6: RAT y registro de repositorios con datos de aspirantes
A7: 5.12 | B7: Clasificación de la información | C7: Organizacional | D7: Etiquetar como restringidos los certificados de discapacidad y fichas socioeconómicas
A8: 5.15 | B8: Control de acceso | C8: Técnico | D8: Acceso por función a carpetas y módulos del SGA
A9: 5.18 | B9: Derechos de acceso | C9: Organizacional | D9: Revisión de accesos al cierre de cada periodo de admisión
A10: 5.19 / 5.20 | B10: Seguridad en relaciones y acuerdos con proveedores | C10: Jurídico | D10: Cláusulas de protección de datos con pasarela, CRM, nube y LMS
A11: 5.24 / 5.26 | B11: Planificación y respuesta a incidentes | C11: Organizacional | D11: Procedimiento de notificación en el término del art. 43 LOPDP
A12: 5.31 | B12: Requisitos legales, regulatorios y contractuales | C12: Jurídico | D12: Matriz de requisitos LOPDP, RLOPDP y resoluciones SPDP
A13: 5.34 | B13: Privacidad y protección de la información personal | C13: Jurídico | D13: Consentimiento por finalidad; aviso de privacidad del formulario
A14: 6.3 | B14: Concienciación, educación y formación | C14: Organizacional | D14: Capacitación al personal de admisiones y temporal
A15: 8.2 | B15: Derechos de acceso privilegiado | C15: Técnico | D15: Cuentas administrativas separadas y registradas
... A25: 8.24 | B25: Uso de criptografía | C25: Técnico | D25: Cifrado en tránsito y en reposo de documentos sensibles

Sheet Delphi
A1: Registro de estimaciones Delphi
A2: Valores ordinales 1–5 (1 = Muy baja/Muy bajo … 5 = Muy alta/Muy alto). Consenso: RIC ≤ 1. Máximo tres rondas.
A4: ID escenario | B4: Variable | C4: Ronda | D4: E01 | E4: E02 | F4: E03 | G4: E04 | H4: E05 | I4: Mediana | J4: Q1 | K4: Q3 | L4: RIC | M4: ¿Consenso? | N4: Nivel (mediana) | O4: Media ponderada (Brier) | P4: Nivel (ponderado)
I5: =IF(COUNT(D5:H5)=0,"",MEDIAN(D5:H5)) | J5: =IF(COUNT(D5:H5)=0,"",QUARTILE(D5:H5,1)) | K5: =IF(COUNT(D5:H5)=0,"",QUARTILE(D5:H5,3)) | L5: =IF(COUNT(D5:H5)=0,"",K5-J5) | M5: =IF(L5="","",IF(L5<=1,"Sí","No")) | N5: =IF(OR(I5="",B5=""),"",IF(B5="Probabilidad",INDEX(Listas!$A$2:$A$6,ROUND(I5,0)),INDEX(Listas!$B$2:$B$6,ROUND(I5,0)))) | O5: =IF(COUNT(D5:H5)<5,"",IFERROR(SUMPRODUCT(D5:H5,Brier!$C$17:$G$17)/SUM(Brier!$C$17:$G$17),"")) | P5: =IF(OR(O5="",B5=""),"",IF(B5="Probabilidad",INDEX(Listas!$A$2:$A$6,ROUND(O5,0)),INDEX(Listas!$B$2:$B$6,ROUND(O5,0))))
I6: =IF(COUNT(D6:H6)=0,"",MEDIAN(D6:H6)) | J6: =IF(COUNT(D6:H6)=0,"",QUARTILE(D6:H6,1)) | K6: =IF(COUNT(D6:H6)=0,"",QUARTILE(D6:H6,3)) | L6: =IF(COUNT(D6:H6)=0,"",K6-J6) | M6: =IF(L6="","",IF(L6<=1,"Sí","No")) | N6: =IF(OR(I6="",B6=""),"",IF(B6="Probabilidad",INDEX(Listas!$A$2:$A$6,ROUND(I6,0)),INDEX(Listas!$B$2:$B$6,ROUND(I6,0)))) | O6: =IF(COUNT(D6:H6)<5,"",IFERROR(SUMPRODUCT(D6:H6,Brier!$C$17:$G$17)/SUM(Brier!$C$17:$G$17),"")) | P6: =IF(OR(O6="",B6=""),"",IF(B6="Probabilidad",INDEX(Listas!$A$2:$A$6,ROUND(O6,0)),INDEX(Listas!$B$2:$B$6,ROUND(O6,0))))
I7: =IF(COUNT(D7:H7)=0,"",MEDIAN(D7:H7)) | J7: =IF(COUNT(D7:H7)=0,"",QUARTILE(D7:H7,1)) | K7: =IF(COUNT(D7:H7)=0,"",QUARTILE(D7:H7,3)) | L7: =IF(COUNT(D7:H7)=0,"",K7-J7) | M7: =IF(L7="","",IF(L7<=1,"Sí","No")) | N7: =IF(OR(I7="",B7=""),"",IF(B7="Probabilidad",INDEX(Listas!$A$2:$A$6,ROUND(I7,0)),INDEX(Listas!$B$2:$B$6,ROUND(I7,0)))) | O7: =IF(COUNT(D7:H7)<5,"",IFERROR(SUMPRODUCT(D7:H7,Brier!$C$17:$G$17)/SUM(Brier!$C$17:$G$17),"")) | P7: =IF(OR(O7="",B7=""),"",IF(B7="Probabilidad",INDEX(Listas!$A$2:$A$6,ROUND(O7,0)),INDEX(Listas!$B$2:$B$6,ROUND(O7,0))))
I8: =IF(COUNT(D8:H8)=0,"",MEDIAN(D8:H8)) | J8: =IF(COUNT(D8:H8)=0,"",QUARTILE(D8:H8,1)) | K8: =IF(COUNT(D8:H8)=0,"",QUARTILE(D8:H8,3)) | L8: =IF(COUNT(D8:H8)=0,"",K8-J8) | M8: =IF(L8="","",IF(L8<=1,"Sí","No")) | N8: =IF(OR(I8="",B8=""),"",IF(B8="Probabilidad",INDEX(Listas!$A$2:$A$6,ROUND(I8,0)),INDEX(Listas!$B$2:$B$6,ROUND(I8,0)))) | O8: =IF(COUNT(D8:H8)<5,"",IFERROR(SUMPRODUCT(D8:H8,Brier!$C$17:$G$17)/SUM(Brier!$C$17:$G$17),"")) | P8: =IF(OR(O8="",B8=""),"",IF(B8="Probabilidad",INDEX(Listas!$A$2:$A$6,ROUND(O8,0)),INDEX(Listas!$B$2:$B$6,ROUND(O8,0))))
I9: =IF(COUNT(D9:H9)=0,"",MEDIAN(D9:H9)) | J9: =IF(COUNT(D9:H9)=0,"",QUARTILE(D9:H9,1)) | K9: =IF(COUNT(D9:H9)=0,"",QUARTILE(D9:H9,3)) | L9: =IF(COUNT(D9:H9)=0,"",K9-J9) | M9: =IF(L9="","",IF(L9<=1,"Sí","No")) | N9: =IF(OR(I9="",B9=""),"",IF(B9="Probabilidad",INDEX(Listas!$A$2:$A$6,ROUND(I9,0)),INDEX(Listas!$B$2:$B$6,ROUND(I9,0)))) | O9: =IF(COUNT(D9:H9)<5,"",IFERROR(SUMPRODUCT(D9:H9,Brier!$C$17:$G$17)/SUM(Brier!$C$17:$G$17),"")) | P9: =IF(OR(O9="",B9=""),"",IF(B9="Probabilidad",INDEX(Listas!$A$2:$A$6,ROUND(O9,0)),INDEX(Listas!$B$2:$B$6,ROUND(O9,0))))
I10: =IF(COUNT(D10:H10)=0,"",MEDIAN(D10:H10)) | J10: =IF(COUNT(D10:H10)=0,"",QUARTILE(D10:H10,1)) | K10: =IF(COUNT(D10:H10)=0,"",QUARTILE(D10:H10,3)) | L10: =IF(COUNT(D10:H10)=0,"",K10-J10) | M10: =IF(L10="","",IF(L10<=1,"Sí","No")) | N10: =IF(OR(I10="",B10=""),"",IF(B10="Probabilidad",INDEX(Listas!$A$2:$A$6,ROUND(I10,0)),INDEX(Listas!$B$2:$B$6,ROUND(I10,0)))) | O10: =IF(COUNT(D10:H10)<5,"",IFERROR(SUMPRODUCT(D10:H10,Brier!$C$17:$G$17)/SUM(Brier!$C$17:$G$17),"")) | P10: =IF(OR(O10="",B10=""),"",IF(B10="Probabilidad",INDEX(Listas!$A$2:$A$6,ROUND(O10,0)),INDEX(Listas!$B$2:$B$6,ROUND(O10,0))))
I11: =IF(COUNT(D11:H11)=0,"",MEDIAN(D11:H11)) | J11: =IF(COUNT(D11:H11)=0,"",QUARTILE(D11:H11,1)) | K11: =IF(COUNT(D11:H11)=0,"",QUARTILE(D11:H11,3)) | L11: =IF(COUNT(D11:H11)=0,"",K11-J11) | M11: =IF(L11="","",IF(L11<=1,"Sí","No")) | N11: =IF(OR(I11="",B11=""),"",IF(B11="Probabilidad",INDEX(Listas!$A$2:$A$6,ROUND(I11,0)),INDEX(Listas!$B$2:$B$6,ROUND(I11,0)))) | O11: =IF(COUNT(D11:H11)<5,"",IFERROR(SUMPRODUCT(D11:H11,Brier!$C$17:$G$17)/SUM(Brier!$C$17:$G$17),"")) | P11: =IF(OR(O11="",B11=""),"",IF(B11="Probabilidad",INDEX(Listas!$A$2:$A$6,ROUND(O11,0)),INDEX(Listas!$B$2:$B$6,ROUND(O11,0))))
I12: =IF(COUNT(D12:H12)=0,"",MEDIAN(D12:H12)) | J12: =IF(COUNT(D12:H12)=0,"",QUARTILE(D12:H12,1)) | K12: =IF(COUNT(D12:H12)=0,"",QUARTILE(D12:H12,3)) | L12: =IF(COUNT(D12:H12)=0,"",K12-J12) | M12: =IF(L12="","",IF(L12<=1,"Sí","No")) | N12: =IF(OR(I12="",B12=""),"",IF(B12="Probabilidad",INDEX(Listas!$A$2:$A$6,ROUND(I12,0)),INDEX(Listas!$B$2:$B$6,ROUND(I12,0)))) | O12: =IF(COUNT(D12:H12)<5,"",IFERROR(SUMPRODUCT(D12:H12,Brier!$C$17:$G$17)/SUM(Brier!$C$17:$G$17),"")) | P12: =IF(OR(O12="",B12=""),"",IF(B12="Probabilidad",INDEX(Listas!$A$2:$A$6,ROUND(O12,0)),INDEX(Listas!$B$2:$B$6,ROUND(O12,0))))
I13: =IF(COUNT(D13:H13)=0,"",MEDIAN(D13:H13)) | J13: =IF(COUNT(D13:H13)=0,"",QUARTILE(D13:H13,1)) | K13: =IF(COUNT(D13:H13)=0,"",QUARTILE(D13:H13,3)) | L13: =IF(COUNT(D13:H13)=0,"",K13-J13) | M13: =IF(L13="","",IF(L13<=1,"Sí","No")) | N13: =IF(OR(I13="",B13=""),"",IF(B13="Probabilidad",INDEX(Listas!$A$2:$A$6,ROUND(I13,0)),INDEX(Listas!$B$2:$B$6,ROUND(I13,0)))) | O13: =IF(COUNT(D13:H13)<5,"",IFERROR(SUMPRODUCT(D13:H13,Brier!$C$17:$G$17)/SUM(Brier!$C$17:$G$17),"")) | P13: =IF(OR(O13="",B13=""),"",IF(B13="Probabilidad",INDEX(Listas!$A$2:$A$6,ROUND(O13,0)),INDEX(Listas!$B$2:$B$6,ROUND(O13,0))))
I14: =IF(COUNT(D14:H14)=0,"",MEDIAN(D14:H14)) | J14: =IF(COUNT(D14:H14)=0,"",QUARTILE(D14:H14,1)) | K14: =IF(COUNT(D14:H14)=0,"",QUARTILE(D14:H14,3)) | L14: =IF(COUNT(D14:H14)=0,"",K14-J14) | M14: =IF(L14="","",IF(L14<=1,"Sí","No")) | N14: =IF(OR(I14="",B14=""),"",IF(B14="Probabilidad",INDEX(Listas!$A$2:$A$6,ROUND(I14,0)),INDEX(Listas!$B$2:$B$6,ROUND(I14,0)))) | O14: =IF(COUNT(D14:H14)<5,"",IFERROR(SUMPRODUCT(D14:H14,Brier!$C$17:$G$17)/SUM(Brier!$C$17:$G$17),"")) | P14: =IF(OR(O14="",B14=""),"",IF(B14="Probabilidad",INDEX(Listas!$A$2:$A$6,ROUND(O14,0)),INDEX(Listas!$B$2:$B$6,ROUND(O14,0))))
I15: =IF(COUNT(D15:H15)=0,"",MEDIAN(D15:H15)) | J15: =IF(COUNT(D15:H15)=0,"",QUARTILE(D15:H15,1)) | K15: =IF(COUNT(D15:H15)=0,"",QUARTILE(D15:H15,3)) | L15: =IF(COUNT(D15:H15)=0,"",K15-J15) | M15: =IF(L15="","",IF(L15<=1,"Sí","No")) | N15: =IF(OR(I15="",B15=""),"",IF(B15="Probabilidad",INDEX(Listas!$A$2:$A$6,ROUND(I15,0)),INDEX(Listas!$B$2:$B$6,ROUND(I15,0)))) | O15: =IF(COUNT(D15:H15)<5,"",IFERROR(SUMPRODUCT(D15:H15,Brier!$C$17:$G$17)/SUM(Brier!$C$17:$G$17),"")) | P15: =IF(OR(O15="",B15=""),"",IF(B15="Probabilidad",INDEX(Listas!$A$2:$A$6,ROUND(O15,0)),INDEX(Listas!$B$2:$B$6,ROUND(O15,0))))
I16: =IF(COUNT(D16:H16)=0,"",MEDIAN(D16:H16)) | J16: =IF(COUNT(D16:H16)=0,"",QUARTILE(D16:H16,1)) | K16: =IF(COUNT(D16:H16)=0,"",QUARTILE(D16:H16,3)) | L16: =IF(COUNT(D16:H16)=0,"",K16-J16) | M16: =IF(L16="","",IF(L16<=1,"Sí","No")) | N16: =IF(OR(I16="",B16=""),"",IF(B16="Probabilidad",INDEX(Listas!$A$2:$A$6,ROUND(I16,0)),INDEX(Listas!$B$2:$B$6,ROUND(I16,0)))) | O16: =IF(COUNT(D16:H16)<5,"",IFERROR(SUMPRODUCT(D16:H16,Brier!$C$17:$G$17)/SUM(Brier!$C$17:$G$17),"")) | P16: =IF(OR(O16="",B16=""),"",IF(B16="Probabilidad",INDEX(Listas!$A$2:$A$6,ROUND(O16,0)),INDEX(Listas!$B$2:$B$6,ROUND(O16,0))))
... I64: =IF(COUNT(D64:H64)=0,"",MEDIAN(D64:H64)) | J64: =IF(COUNT(D64:H64)=0,"",QUARTILE(D64:H64,1)) | K64: =IF(COUNT(D64:H64)=0,"",QUARTILE(D64:H64,3)) | L64: =IF(COUNT(D64:H64)=0,"",K64-J64) | M64: =IF(L64="","",IF(L64<=1,"Sí","No")) | N64: =IF(OR(I64="",B64=""),"",IF(B64="Probabilidad",INDEX(Listas!$A$2:$A$6,ROUND(I64,0)),INDEX(Listas!$B$2:$B$6,ROUND(I64,0)))) | O64: =IF(COUNT(D64:H64)<5,"",IFERROR(SUMPRODUCT(D64:H64,Brier!$C$17:$G$17)/SUM(Brier!$C$17:$G$17),"")) | P64: =IF(OR(O64="",B64=""),"",IF(B64="Probabilidad",INDEX(Listas!$A$2:$A$6,ROUND(O64,0)),INDEX(Listas!$B$2:$B$6,ROUND(O64,0))))
A66: La fila 5 es un EJEMPLO ficticio; borrarla antes de aplicar el instrumento. La media ponderada usa los pesos de la hoja Brier y requiere las cinco respuestas.

Sheet Brier
A1: Calibración de expertos — puntaje de Brier
A2: Cada experto indica la probabilidad (0 a 1) de que la afirmación sea verdadera. BS = (1/N)·Σ(f − o)². Umbral: BS ≤ 0,25.
A4: ID | B4: Afirmación de calibración | C4: E01 | D4: E02 | E4: E03 | F4: E04 | G4: E05 | H4: Resultado real (1 = verdadera, 0 = falsa) | I4: Fuente de verificación
A5: C01 | B5: La LOPDP se publicó en el Registro Oficial en 2021. | H5: 1 | I5: R.O. Quinto Supl. 459, 26-05-2021
A6: C02 | B6: El art. 43 de la LOPDP fija un término de cinco días para notificar vulneraciones a la autoridad. | H6: 1 | I6: LOPDP art. 43
A7: C03 | B7: ISO/IEC 27005:2022 es una norma certificable. | H7: 0 | I7: ISO/IEC 27005:2022 (norma de orientación)
A8: C04 | B8: El Reglamento General a la LOPDP se expidió mediante Decreto Ejecutivo N.º 904. | H8: 1 | I8: R.O. Tercer Supl. 435, 13-11-2023
A9: C05 | B9: Según Sophos (2024), más del 60 % de las IES encuestadas sufrió ransomware en el último año. | H9: 1 | I9: Sophos, State of Ransomware in Education 2024 (66 %)
A10: C06 | B10: ISO/IEC 27002:2022 agrupa sus controles en cuatro temas. | H10: 1 | I10: ISO/IEC 27002:2022
A11: C07 | B11: ISO/IEC 27002:2022 contiene más de 100 controles. | H11: 0 | I11: ISO/IEC 27002:2022 (93 controles)
A12: C08 | B12: El RGPD europeo es aplicable desde mayo de 2018. | H12: 1 | I12: Reglamento (UE) 2016/679, art. 99
A13: C09 | B13: LINDDUN incluye la categoría de amenaza "Spoofing". | H13: 0 | I13: Deng et al. (2011)
A14: C10 | B14: La Res. SPDP-SPD-2026-0005-R regula el tratamiento de datos personales a gran escala. | H14: 1 | I14: R.O. Supl. 231, 25-02-2026
